Workbook

Sheet טבלת אב
A1: מקור | B1: נסיין | C1: מגדר | D1: סדר | E1: זמן A (לבד) | F1: זמן B (כלב) | G1: זמן B2 (כלב#2) | H1: זמן C (רצועה) | I1: האטה B−A | J1: האטה C−A | K1: התרגלות B1−B2 | L1: טבעי A | M1: בטוח A | N1: קצב A | O1: שינוי A | P1: טבעי B | Q1: בטוח B | R1: קצב B | S1: שינוי B | T1: נוח B | U1: טבעי C | V1: בטוח C | W1: קצב C | X1: שינוי C | Y1: נוח C | Z1: חשש | AA1: שותף | AB1: ביטחון-ללא | AC1: ביטחון-עם | AD1: שליטה-ללא | AE1: שליטה-עם | AF1: הנאה | AG1: מוטיבציה | AH1: Δטבעי B−A | AI1: Δבטוח B−A | AJ1: Δקצב B−A | AK1: Δשינוי B−A | AL1: Δביטחון רצועה | AM1: Δשליטה רצועה | AN1: הפרש C−B | AO1: % האטה B | AP1: % האטה C | AQ1: % האטה B2
A2: ABB | B2: 183 | C2: אישה | D2: A, B, B | E2: 16.12 | F2: 17.1 | G2: 17.29 | I2: =IF(COUNT(E2,F2)=2,F2-E2,"") -> 0.98 | J2: =IF(COUNT(E2,H2)=2,H2-E2,"") | K2: =IF(COUNT(F2,G2)=2,F2-G2,"") -> -0.19 | L2: 9 | M2: 9 | N2: 9 | O2: 1 | P2: 9 | Q2: 9 | R2: 9 | S2: 4 | T2: 7 | Z2: לא | AA2: בהליכה עם רצועה | AB2: 9 | AC2: 9 | AD2: 9 | AE2: 9 | AF2: 9 | AG2: 9 | AH2: =IF(COUNT(L2,P2)=2,P2-L2,"") -> 0 | AI2: =IF(COUNT(M2,Q2)=2,Q2-M2,"") -> 0 | AJ2: =IF(COUNT(N2,R2)=2,R2-N2,"") -> 0 | AK2: =IF(COUNT(O2,S2)=2,S2-O2,"") -> 3 | AL2: =IF(COUNT(AB2,AC2)=2,AC2-AB2,"") -> 0 | AM2: =IF(COUNT(AD2,AE2)=2,AE2-AD2,"") -> 0 | AN2: =IF(COUNT(F2,H2)=2,H2-F2,"") | AO2: =IF(COUNT(E2,F2)=2,(F2-E2)/E2,"") -> 0.060794045 | AP2: =IF(COUNT(E2,H2)=2,(H2-E2)/E2,"") | AQ2: =IF(COUNT(E2,G2)=2,(G2-E2)/E2,"") -> 0.072580645
A3: ABB | B3: 184 | C3: גבר | D3: B, A, B | E3: 16.06 | F3: 26.1 | I3: =IF(COUNT(E3,F3)=2,F3-E3,"") -> 10.04 | J3: =IF(COUNT(E3,H3)=2,H3-E3,"") | K3: =IF(COUNT(F3,G3)=2,F3-G3,"") | L3: 9 | M3: 9 | N3: 9 | O3: 1 | P3: 4 | Q3: 4 | R3: 5 | S3: 7 | T3: 4 | AH3: =IF(COUNT(L3,P3)=2,P3-L3,"") -> -5 | AI3: =IF(COUNT(M3,Q3)=2,Q3-M3,"") -> -5 | AJ3: =IF(COUNT(N3,R3)=2,R3-N3,"") -> -4 | AK3: =IF(COUNT(O3,S3)=2,S3-O3,"") -> 6 | AL3: =IF(COUNT(AB3,AC3)=2,AC3-AB3,"") | AM3: =IF(COUNT(AD3,AE3)=2,AE3-AD3,"") | AN3: =IF(COUNT(F3,H3)=2,H3-F3,"") | AO3: =IF(COUNT(E3,F3)=2,(F3-E3)/E3,"") -> 0.62515567 | AP3: =IF(COUNT(E3,H3)=2,(H3-E3)/E3,"") | AQ3: =IF(COUNT(E3,G3)=2,(G3-E3)/E3,"")
A4: ABB | B4: 185 | C4: גבר | D4: B, B, A | E4: 11.19 | F4: 14.22 | G4: 12.16 | I4: =IF(COUNT(E4,F4)=2,F4-E4,"") -> 3.03 | J4: =IF(COUNT(E4,H4)=2,H4-E4,"") | K4: =IF(COUNT(F4,G4)=2,F4-G4,"") -> 2.06 | L4: 7 | M4: 7 | N4: 7 | O4: 2 | P4: 6 | Q4: 5.5 | R4: 5.5 | S4: 5.5 | T4: 5.5 | Z4: לא | AA4: אף פעם לא הרגשתי שהוא שותף להליכה | AB4: 6 | AC4: 1 | AD4: 6 | AE4: 1 | AF4: 6 | AG4: 1 | AH4: =IF(COUNT(L4,P4)=2,P4-L4,"") -> -1 | AI4: =IF(COUNT(M4,Q4)=2,Q4-M4,"") -> -1.5 | AJ4: =IF(COUNT(N4,R4)=2,R4-N4,"") -> -1.5 | AK4: =IF(COUNT(O4,S4)=2,S4-O4,"") -> 3.5 | AL4: =IF(COUNT(AB4,AC4)=2,AC4-AB4,"") -> -5 | AM4: =IF(COUNT(AD4,AE4)=2,AE4-AD4,"") -> -5 | AN4: =IF(COUNT(F4,H4)=2,H4-F4,"") | AO4: =IF(COUNT(E4,F4)=2,(F4-E4)/E4,"") -> 0.27077748 | AP4: =IF(COUNT(E4,H4)=2,(H4-E4)/E4,"") | AQ4: =IF(COUNT(E4,G4)=2,(G4-E4)/E4,"") -> 0.08668454
A5: ABB | B5: 186 | C5: גבר | D5: A, B, B | E5: 14.56 | F5: 15.16 | G5: 13.84 | I5: =IF(COUNT(E5,F5)=2,F5-E5,"") -> 0.6 | J5: =IF(COUNT(E5,H5)=2,H5-E5,"") | K5: =IF(COUNT(F5,G5)=2,F5-G5,"") -> 1.32 | L5: 9 | M5: 9 | N5: 9 | O5: 1 | P5: 7.5 | Q5: 7.5 | R5: 8.5 | S5: 5 | T5: 7 | AH5: =IF(COUNT(L5,P5)=2,P5-L5,"") -> -1.5 | AI5: =IF(COUNT(M5,Q5)=2,Q5-M5,"") -> -1.5 | AJ5: =IF(COUNT(N5,R5)=2,R5-N5,"") -> -0.5 | AK5: =IF(COUNT(O5,S5)=2,S5-O5,"") -> 4 | AL5: =IF(COUNT(AB5,AC5)=2,AC5-AB5,"") | AM5: =IF(COUNT(AD5,AE5)=2,AE5-AD5,"") | AN5: =IF(COUNT(F5,H5)=2,H5-F5,"") | AO5: =IF(COUNT(E5,F5)=2,(F5-E5)/E5,"") -> 0.041208791 | AP5: =IF(COUNT(E5,H5)=2,(H5-E5)/E5,"") | AQ5: =IF(COUNT(E5,G5)=2,(G5-E5)/E5,"") -> -0.049450549
A6: ABB | B6: 187 | C6: גבר | D6: B, A, B | E6: 16.41 | F6: 18.72 | G6: 16.78 | I6: =IF(COUNT(E6,F6)=2,F6-E6,"") -> 2.31 | J6: =IF(COUNT(E6,H6)=2,H6-E6,"") | K6: =IF(COUNT(F6,G6)=2,F6-G6,"") -> 1.94 | L6: 9 | M6: 9 | N6: 9 | O6: 2 | P6: 8 | Q6: 9 | R6: 8 | S6: 1.5 | T6: 8.5 | AH6: =IF(COUNT(L6,P6)=2,P6-L6,"") -> -1 | AI6: =IF(COUNT(M6,Q6)=2,Q6-M6,"") -> 0 | AJ6: =IF(COUNT(N6,R6)=2,R6-N6,"") -> -1 | AK6: =IF(COUNT(O6,S6)=2,S6-O6,"") -> -0.5 | AL6: =IF(COUNT(AB6,AC6)=2,AC6-AB6,"") | AM6: =IF(COUNT(AD6,AE6)=2,AE6-AD6,"") | AN6: =IF(COUNT(F6,H6)=2,H6-F6,"") | AO6: =IF(COUNT(E6,F6)=2,(F6-E6)/E6,"") -> 0.14076782 | AP6: =IF(COUNT(E6,H6)=2,(H6-E6)/E6,"") | AQ6: =IF(COUNT(E6,G6)=2,(G6-E6)/E6,"") -> 0.022547227
A7: ABB | B7: 188 | C7: גבר | D7: B, A, B | E7: 16.97 | F7: 20.25 | G7: 16.25 | I7: =IF(COUNT(E7,F7)=2,F7-E7,"") -> 3.28 | J7: =IF(COUNT(E7,H7)=2,H7-E7,"") | K7: =IF(COUNT(F7,G7)=2,F7-G7,"") -> 4 | L7: 9 | M7: 9 | N7: 9 | O7: 1 | P7: 8 | Q7: 7.5 | R7: 9 | S7: 3 | T7: 8.5 | AH7: =IF(COUNT(L7,P7)=2,P7-L7,"") -> -1 | AI7: =IF(COUNT(M7,Q7)=2,Q7-M7,"") -> -1.5 | AJ7: =IF(COUNT(N7,R7)=2,R7-N7,"") -> 0 | AK7: =IF(COUNT(O7,S7)=2,S7-O7,"") -> 2 | AL7: =IF(COUNT(AB7,AC7)=2,AC7-AB7,"") | AM7: =IF(COUNT(AD7,AE7)=2,AE7-AD7,"") | AN7: =IF(COUNT(F7,H7)=2,H7-F7,"") | AO7: =IF(COUNT(E7,F7)=2,(F7-E7)/E7,"") -> 0.19328226 | AP7: =IF(COUNT(E7,H7)=2,(H7-E7)/E7,"") | AQ7: =IF(COUNT(E7,G7)=2,(G7-E7)/E7,"") -> -0.042427814
A8: ABB | B8: 189 | C8: גבר | D8: B, B, A | E8: 16.6 | F8: 17.22 | G8: 17.35 | I8: =IF(COUNT(E8,F8)=2,F8-E8,"") -> 0.62 | J8: =IF(COUNT(E8,H8)=2,H8-E8,"") | K8: =IF(COUNT(F8,G8)=2,F8-G8,"") -> -0.13 | L8: 5 | M8: 8 | N8: 5 | O8: 7 | P8: 6.5 | Q8: 8.5 | R8: 3.5 | S8: 8 | T8: 8 | AH8: =IF(COUNT(L8,P8)=2,P8-L8,"") -> 1.5 | AI8: =IF(COUNT(M8,Q8)=2,Q8-M8,"") -> 0.5 | AJ8: =IF(COUNT(N8,R8)=2,R8-N8,"") -> -1.5 | AK8: =IF(COUNT(O8,S8)=2,S8-O8,"") -> 1 | AL8: =IF(COUNT(AB8,AC8)=2,AC8-AB8,"") | AM8: =IF(COUNT(AD8,AE8)=2,AE8-AD8,"") | AN8: =IF(COUNT(F8,H8)=2,H8-F8,"") | AO8: =IF(COUNT(E8,F8)=2,(F8-E8)/E8,"") -> 0.037349398 | AP8: =IF(COUNT(E8,H8)=2,(H8-E8)/E8,"") | AQ8: =IF(COUNT(E8,G8)=2,(G8-E8)/E8,"") -> 0.045180723
A9: ABB | B9: 190 | C9: גבר | D9: B, B, A | E9: 16.07 | F9: 18.5 | G9: 17.25 | I9: =IF(COUNT(E9,F9)=2,F9-E9,"") -> 2.43 | J9: =IF(COUNT(E9,H9)=2,H9-E9,"") | K9: =IF(COUNT(F9,G9)=2,F9-G9,"") -> 1.25 | L9: 8 | M9: 9 | N9: 7 | O9: 1 | P9: 8 | Q9: 7 | R9: 8.5 | S9: 1 | T9: 6.5 | AH9: =IF(COUNT(L9,P9)=2,P9-L9,"") -> 0 | AI9: =IF(COUNT(M9,Q9)=2,Q9-M9,"") -> -2 | AJ9: =IF(COUNT(N9,R9)=2,R9-N9,"") -> 1.5 | AK9: =IF(COUNT(O9,S9)=2,S9-O9,"") -> 0 | AL9: =IF(COUNT(AB9,AC9)=2,AC9-AB9,"") | AM9: =IF(COUNT(AD9,AE9)=2,AE9-AD9,"") | AN9: =IF(COUNT(F9,H9)=2,H9-F9,"") | AO9: =IF(COUNT(E9,F9)=2,(F9-E9)/E9,"") -> 0.15121344 | AP9: =IF(COUNT(E9,H9)=2,(H9-E9)/E9,"") | AQ9: =IF(COUNT(E9,G9)=2,(G9-E9)/E9,"") -> 0.073428749
A10: ABB | B10: 191 | C10: אישה | D10: A, B, B | E10: 14.5 | F10: 15.6 | G10: 14.96 | I10: =IF(COUNT(E10,F10)=2,F10-E10,"") -> 1.1 | J10: =IF(COUNT(E10,H10)=2,H10-E10,"") | K10: =IF(COUNT(F10,G10)=2,F10-G10,"") -> 0.64 | L10: 9 | M10: 9 | N10: 9 | O10: 1 | P10: 9 | Q10: 9 | R10: 9 | S10: 1 | T10: 9 | AH10: =IF(COUNT(L10,P10)=2,P10-L10,"") -> 0 | AI10: =IF(COUNT(M10,Q10)=2,Q10-M10,"") -> 0 | AJ10: =IF(COUNT(N10,R10)=2,R10-N10,"") -> 0 | AK10: =IF(COUNT(O10,S10)=2,S10-O10,"") -> 0 | AL10: =IF(COUNT(AB10,AC10)=2,AC10-AB10,"") | AM10: =IF(COUNT(AD10,AE10)=2,AE10-AD10,"") | AN10: =IF(COUNT(F10,H10)=2,H10-F10,"") | AO10: =IF(COUNT(E10,F10)=2,(F10-E10)/E10,"") -> 0.075862069 | AP10: =IF(COUNT(E10,H10)=2,(H10-E10)/E10,"") | AQ10: =IF(COUNT(E10,G10)=2,(G10-E10)/E10,"") -> 0.031724138
A11: ABB | B11: 192 | C11: אישה | D11: B, A, B | E11: 14.06 | F11: 15.09 | G11: 14.06 | I11: =IF(COUNT(E11,F11)=2,F11-E11,"") -> 1.03 | J11: =IF(COUNT(E11,H11)=2,H11-E11,"") | K11: =IF(COUNT(F11,G11)=2,F11-G11,"") -> 1.03 | L11: 9 | M11: 9 | N11: 9 | O11: 1 | P11: 9 | Q11: 6.5 | R11: 8.5 | S11: 6.5 | T11: 6.5 | AH11: =IF(COUNT(L11,P11)=2,P11-L11,"") -> 0 | AI11: =IF(COUNT(M11,Q11)=2,Q11-M11,"") -> -2.5 | AJ11: =IF(COUNT(N11,R11)=2,R11-N11,"") -> -0.5 | AK11: =IF(COUNT(O11,S11)=2,S11-O11,"") -> 5.5 | AL11: =IF(COUNT(AB11,AC11)=2,AC11-AB11,"") | AM11: =IF(COUNT(AD11,AE11)=2,AE11-AD11,"") | AN11: =IF(COUNT(F11,H11)=2,H11-F11,"") | AO11: =IF(COUNT(E11,F11)=2,(F11-E11)/E11,"") -> 0.073257468 | AP11: =IF(COUNT(E11,H11)=2,(H11-E11)/E11,"") | AQ11: =IF(COUNT(E11,G11)=2,(G11-E11)/E11,"") -> 0
A12: ABB | B12: 193 | C12: גבר | D12: A, B, B | E12: 15.63 | F12: 15.53 | G12: 14.63 | I12: =IF(COUNT(E12,F12)=2,F12-E12,"") -> -0.1 | J12: =IF(COUNT(E12,H12)=2,H12-E12,"") | K12: =IF(COUNT(F12,G12)=2,F12-G12,"") -> 0.9 | L12: 9 | M12: 9 | N12: 9 | O12: 1 | P12: 9 | Q12: 8.5 | R12: 8.5 | S12: 1.5 | T12: 8.5 | AH12: =IF(COUNT(L12,P12)=2,P12-L12,"") -> 0 | AI12: =IF(COUNT(M12,Q12)=2,Q12-M12,"") -> -0.5 | AJ12: =IF(COUNT(N12,R12)=2,R12-N12,"") -> -0.5 | AK12: =IF(COUNT(O12,S12)=2,S12-O12,"") -> 0.5 | AL12: =IF(COUNT(AB12,AC12)=2,AC12-AB12,"") | AM12: =IF(COUNT(AD12,AE12)=2,AE12-AD12,"") | AN12: =IF(COUNT(F12,H12)=2,H12-F12,"") | AO12: =IF(COUNT(E12,F12)=2,(F12-E12)/E12,"") -> -0.0063979527 | AP12: =IF(COUNT(E12,H12)=2,(H12-E12)/E12,"") | AQ12: =IF(COUNT(E12,G12)=2,(G12-E12)/E12,"") -> -0.063979527
A13: ABB | B13: 194 | C13: אישה | D13: B, B, A | E13: 13.37 | F13: 17.1 | G13: 16.66 | I13: =IF(COUNT(E13,F13)=2,F13-E13,"") -> 3.73 | J13: =IF(COUNT(E13,H13)=2,H13-E13,"") | K13: =IF(COUNT(F13,G13)=2,F13-G13,"") -> 0.44 | L13: 9 | M13: 9 | N13: 9 | O13: 1 | P13: 6 | Q13: 8.5 | R13: 8 | S13: 7.5 | T13: 8.5 | AH13: =IF(COUNT(L13,P13)=2,P13-L13,"") -> -3 | AI13: =IF(COUNT(M13,Q13)=2,Q13-M13,"") -> -0.5 | AJ13: =IF(COUNT(N13,R13)=2,R13-N13,"") -> -1 | AK13: =IF(COUNT(O13,S13)=2,S13-O13,"") -> 6.5 | AL13: =IF(COUNT(AB13,AC13)=2,AC13-AB13,"") | AM13: =IF(COUNT(AD13,AE13)=2,AE13-AD13,"") | AN13: =IF(COUNT(F13,H13)=2,H13-F13,"") | AO13: =IF(COUNT(E13,F13)=2,(F13-E13)/E13,"") -> 0.2789828 | AP13: =IF(COUNT(E13,H13)=2,(H13-E13)/E13,"") | AQ13: =IF(COUNT(E13,G13)=2,(G13-E13)/E13,"") -> 0.2460733
A14: ABB | B14: 195 | C14: גבר | D14: B, A, B | E14: 14.91 | F14: 18.37 | G14: 15.57 | I14: =IF(COUNT(E14,F14)=2,F14-E14,"") -> 3.46 | J14: =IF(COUNT(E14,H14)=2,H14-E14,"") | K14: =IF(COUNT(F14,G14)=2,F14-G14,"") -> 2.8 | L14: 9 | M14: 9 | N14: 9 | O14: 1 | P14: 7.5 | Q14: 9 | R14: 8 | S14: 2 | T14: 9 | AH14: =IF(COUNT(L14,P14)=2,P14-L14,"") -> -1.5 | AI14: =IF(COUNT(M14,Q14)=2,Q14-M14,"") -> 0 | AJ14: =IF(COUNT(N14,R14)=2,R14-N14,"") -> -1 | AK14: =IF(COUNT(O14,S14)=2,S14-O14,"") -> 1 | AL14: =IF(COUNT(AB14,AC14)=2,AC14-AB14,"") | AM14: =IF(COUNT(AD14,AE14)=2,AE14-AD14,"") | AN14: =IF(COUNT(F14,H14)=2,H14-F14,"") | AO14: =IF(COUNT(E14,F14)=2,(F14-E14)/E14,"") -> 0.23205902 | AP14: =IF(COUNT(E14,H14)=2,(H14-E14)/E14,"") | AQ14: =IF(COUNT(E14,G14)=2,(G14-E14)/E14,"") -> 0.044265594
A15: ABB | B15: 196 | C15: גבר | D15: A, B, B | E15: 15.84 | F15: 18.43 | G15: 18.4 | I15: =IF(COUNT(E15,F15)=2,F15-E15,"") -> 2.59 | J15: =IF(COUNT(E15,H15)=2,H15-E15,"") | K15: =IF(COUNT(F15,G15)=2,F15-G15,"") -> 0.03 | L15: 9 | M15: 9 | N15: 9 | O15: 9 | P15: 7 | Q15: 8.5 | R15: 7 | S15: 6 | T15: 8.5 | AH15: =IF(COUNT(L15,P15)=2,P15-L15,"") -> -2 | AI15: =IF(COUNT(M15,Q15)=2,Q15-M15,"") -> -0.5 | AJ15: =IF(COUNT(N15,R15)=2,R15-N15,"") -> -2 | AK15: =IF(COUNT(O15,S15)=2,S15-O15,"") -> -3 | AL15: =IF(COUNT(AB15,AC15)=2,AC15-AB15,"") | AM15: =IF(COUNT(AD15,AE15)=2,AE15-AD15,"") | AN15: =IF(COUNT(F15,H15)=2,H15-F15,"") | AO15: =IF(COUNT(E15,F15)=2,(F15-E15)/E15,"") -> 0.1635101 | AP15: =IF(COUNT(E15,H15)=2,(H15-E15)/E15,"") | AQ15: =IF(COUNT(E15,G15)=2,(G15-E15)/E15,"") -> 0.16161616
A16: ABB | B16: 197 | C16: גבר | D16: B, B, A | E16: 13.46 | F16: 15.22 | G16: 15 | I16: =IF(COUNT(E16,F16)=2,F16-E16,"") -> 1.76 | J16: =IF(COUNT(E16,H16)=2,H16-E16,"") | K16: =IF(COUNT(F16,G16)=2,F16-G16,"") -> 0.22 | L16: 9 | M16: 9 | N16: 8 | O16: 2 | P16: 6.5 | Q16: 7 | R16: 5.5 | S16: 5 | T16: 7.5 | AH16: =IF(COUNT(L16,P16)=2,P16-L16,"") -> -2.5 | AI16: =IF(COUNT(M16,Q16)=2,Q16-M16,"") -> -2 | AJ16: =IF(COUNT(N16,R16)=2,R16-N16,"") -> -2.5 | AK16: =IF(COUNT(O16,S16)=2,S16-O16,"") -> 3 | AL16: =IF(COUNT(AB16,AC16)=2,AC16-AB16,"") | AM16: =IF(COUNT(AD16,AE16)=2,AE16-AD16,"") | AN16: =IF(COUNT(F16,H16)=2,H16-F16,"") | AO16: =IF(COUNT(E16,F16)=2,(F16-E16)/E16,"") -> 0.1307578 | AP16: =IF(COUNT(E16,H16)=2,(H16-E16)/E16,"") | AQ16: =IF(COUNT(E16,G16)=2,(G16-E16)/E16,"") -> 0.11441308
... A21: ABB | B21: 202 | C21: גבר | D21: B, B, A | E21: 17.75 | F21: 22.16 | G21: 20.22 | I21: =IF(COUNT(E21,F21)=2,F21-E21,"") -> 4.41 | J21: =IF(COUNT(E21,H21)=2,H21-E21,"") | K21: =IF(COUNT(F21,G21)=2,F21-G21,"") -> 1.94 | L21: 9 | M21: 9 | N21: 8 | O21: 2 | P21: 9 | Q21: 9 | R21: 8 | S21: 2.5 | T21: 9 | AH21: =IF(COUNT(L21,P21)=2,P21-L21,"") -> 0 | AI21: =IF(COUNT(M21,Q21)=2,Q21-M21,"") -> 0 | AJ21: =IF(COUNT(N21,R21)=2,R21-N21,"") -> 0 | AK21: =IF(COUNT(O21,S21)=2,S21-O21,"") -> 0.5 | AL21: =IF(COUNT(AB21,AC21)=2,AC21-AB21,"") | AM21: =IF(COUNT(AD21,AE21)=2,AE21-AD21,"") | AN21: =IF(COUNT(F21,H21)=2,H21-F21,"") | AO21: =IF(COUNT(E21,F21)=2,(F21-E21)/E21,"") -> 0.2484507 | AP21: =IF(COUNT(E21,H21)=2,(H21-E21)/E21,"") | AQ21: =IF(COUNT(E21,G21)=2,(G21-E21)/E21,"") -> 0.13915493
A22: ABC | B22: 106 | C22: גבר | D22: BAC | E22: 15.09 | F22: 20 | H22: 16.96 | I22: =IF(COUNT(E22,F22)=2,F22-E22,"") -> 4.91 | J22: =IF(COUNT(E22,H22)=2,H22-E22,"") -> 1.87 | K22: =IF(COUNT(F22,G22)=2,F22-G22,"") | L22: 9 | M22: 9 | N22: 9 | O22: 1 | P22: 8 | Q22: 6 | R22: 8 | S22: 2 | T22: 8 | U22: 9 | V22: 8 | W22: 9 | X22: 1 | Y22: 8 | Z22: כן | AA22: בהליכה עם רצועה | AB22: 7 | AC22: 9 | AD22: 7 | AE22: 8 | AH22: =IF(COUNT(L22,P22)=2,P22-L22,"") -> -1 | AI22: =IF(COUNT(M22,Q22)=2,Q22-M22,"") -> -3 | AJ22: =IF(COUNT(N22,R22)=2,R22-N22,"") -> -1 | AK22: =IF(COUNT(O22,S22)=2,S22-O22,"") -> 1 | AL22: =IF(COUNT(AB22,AC22)=2,AC22-AB22,"") -> 2 | AM22: =IF(COUNT(AD22,AE22)=2,AE22-AD22,"") -> 1 | AN22: =IF(COUNT(F22,H22)=2,H22-F22,"") -> -3.04 | AO22: =IF(COUNT(E22,F22)=2,(F22-E22)/E22,"") -> 0.32538105 | AP22: =IF(COUNT(E22,H22)=2,(H22-E22)/E22,"") -> 0.12392313 | AQ22: =IF(COUNT(E22,G22)=2,(G22-E22)/E22,"")
A23: ABC | B23: 107 | C23: אישה | D23: CAB | E23: 14.56 | F23: 14.2 | H23: 16.16 | I23: =IF(COUNT(E23,F23)=2,F23-E23,"") -> -0.36 | J23: =IF(COUNT(E23,H23)=2,H23-E23,"") -> 1.6 | K23: =IF(COUNT(F23,G23)=2,F23-G23,"") | L23: 8 | M23: 9 | N23: 7 | O23: 1 | P23: 8 | Q23: 6 | R23: 7 | S23: 6 | T23: 7 | U23: 7 | V23: 8 | W23: 6 | X23: 6 | Y23: 7 | Z23: לא | AA23: לא הרגשתי הבדל בין המצבים | AB23: 7 | AC23: 7 | AD23: 2 | AE23: 5 | AH23: =IF(COUNT(L23,P23)=2,P23-L23,"") -> 0 | AI23: =IF(COUNT(M23,Q23)=2,Q23-M23,"") -> -3 | AJ23: =IF(COUNT(N23,R23)=2,R23-N23,"") -> 0 | AK23: =IF(COUNT(O23,S23)=2,S23-O23,"") -> 5 | AL23: =IF(COUNT(AB23,AC23)=2,AC23-AB23,"") -> 0 | AM23: =IF(COUNT(AD23,AE23)=2,AE23-AD23,"") -> 3 | AN23: =IF(COUNT(F23,H23)=2,H23-F23,"") -> 1.96 | AO23: =IF(COUNT(E23,F23)=2,(F23-E23)/E23,"") -> -0.024725275 | AP23: =IF(COUNT(E23,H23)=2,(H23-E23)/E23,"") -> 0.10989011 | AQ23: =IF(COUNT(E23,G23)=2,(G23-E23)/E23,"")
A24: ABC | B24: 108 | C24: גבר | D24: ACB | E24: 16.4 | F24: 16.5 | H24: 17.31 | I24: =IF(COUNT(E24,F24)=2,F24-E24,"") -> 0.1 | J24: =IF(COUNT(E24,H24)=2,H24-E24,"") -> 0.91 | K24: =IF(COUNT(F24,G24)=2,F24-G24,"") | L24: 8 | M24: 8 | N24: 7 | O24: 2 | P24: 9 | Q24: 9 | R24: 9 | S24: 1 | T24: 9 | U24: 9 | V24: 9 | W24: 8 | X24: 2 | Y24: 9 | Z24: לא | AA24: בהליכה עם רצועה | AB24: 8 | AC24: 9 | AD24: 8 | AE24: 8 | AH24: =IF(COUNT(L24,P24)=2,P24-L24,"") -> 1 | AI24: =IF(COUNT(M24,Q24)=2,Q24-M24,"") -> 1 | AJ24: =IF(COUNT(N24,R24)=2,R24-N24,"") -> 2 | AK24: =IF(COUNT(O24,S24)=2,S24-O24,"") -> -1 | AL24: =IF(COUNT(AB24,AC24)=2,AC24-AB24,"") -> 1 | AM24: =IF(COUNT(AD24,AE24)=2,AE24-AD24,"") -> 0 | AN24: =IF(COUNT(F24,H24)=2,H24-F24,"") -> 0.81 | AO24: =IF(COUNT(E24,F24)=2,(F24-E24)/E24,"") -> 0.006097561 | AP24: =IF(COUNT(E24,H24)=2,(H24-E24)/E24,"") -> 0.055487805 | AQ24: =IF(COUNT(E24,G24)=2,(G24-E24)/E24,"")
A25: ABC | B25: 109 | C25: גבר | D25: BCA | E25: 14.16 | F25: 20.11 | H25: 19.4 | I25: =IF(COUNT(E25,F25)=2,F25-E25,"") -> 5.95 | J25: =IF(COUNT(E25,H25)=2,H25-E25,"") -> 5.24 | K25: =IF(COUNT(F25,G25)=2,F25-G25,"") | L25: 7 | M25: 9 | N25: 9 | O25: 1 | P25: 6 | Q25: 6 | R25: 7 | S25: 3 | T25: 6 | U25: 4 | V25: 3 | W25: 7 | X25: 6 | Y25: 4 | Z25: לא | AA25: בהליכה עם רצועה | AB25: 6 | AC25: 3 | AD25: 3 | AE25: 5 | AH25: =IF(COUNT(L25,P25)=2,P25-L25,"") -> -1 | AI25: =IF(COUNT(M25,Q25)=2,Q25-M25,"") -> -3 | AJ25: =IF(COUNT(N25,R25)=2,R25-N25,"") -> -2 | AK25: =IF(COUNT(O25,S25)=2,S25-O25,"") -> 2 | AL25: =IF(COUNT(AB25,AC25)=2,AC25-AB25,"") -> -3 | AM25: =IF(COUNT(AD25,AE25)=2,AE25-AD25,"") -> 2 | AN25: =IF(COUNT(F25,H25)=2,H25-F25,"") -> -0.71 | AO25: =IF(COUNT(E25,F25)=2,(F25-E25)/E25,"") -> 0.42019774 | AP25: =IF(COUNT(E25,H25)=2,(H25-E25)/E25,"") -> 0.3700565 | AQ25: =IF(COUNT(E25,G25)=2,(G25-E25)/E25,"")
A26: ABC | B26: 110 | C26: גבר | D26: ABC | E26: 15.31 | F26: 19.13 | H26: 15.35 | I26: =IF(COUNT(E26,F26)=2,F26-E26,"") -> 3.82 | J26: =IF(COUNT(E26,H26)=2,H26-E26,"") -> 0.04 | K26: =IF(COUNT(F26,G26)=2,F26-G26,"") | L26: 9 | M26: 9 | N26: 9 | O26: 9 | P26: 9 | Q26: 9 | R26: 9 | S26: 1 | T26: 9 | U26: 9 | V26: 9 | W26: 9 | X26: 1 | Y26: 9 | Z26: לא | AA26: אף פעם לא הרגשתי שהוא שותף להליכה | AB26: 9 | AC26: 9 | AD26: 1 | AE26: 5 | AH26: =IF(COUNT(L26,P26)=2,P26-L26,"") -> 0 | AI26: =IF(COUNT(M26,Q26)=2,Q26-M26,"") -> 0 | AJ26: =IF(COUNT(N26,R26)=2,R26-N26,"") -> 0 | AK26: =IF(COUNT(O26,S26)=2,S26-O26,"") -> -8 | AL26: =IF(COUNT(AB26,AC26)=2,AC26-AB26,"") -> 0 | AM26: =IF(COUNT(AD26,AE26)=2,AE26-AD26,"") -> 4 | AN26: =IF(COUNT(F26,H26)=2,H26-F26,"") -> -3.78 | AO26: =IF(COUNT(E26,F26)=2,(F26-E26)/E26,"") -> 0.24951012 | AP26: =IF(COUNT(E26,H26)=2,(H26-E26)/E26,"") -> 0.0026126715 | AQ26: =IF(COUNT(E26,G26)=2,(G26-E26)/E26,"")
A27: ABC | B27: 111 | C27: אישה | D27: ACB | E27: 18.62 | F27: 18.16 | H27: 18.4 | I27: =IF(COUNT(E27,F27)=2,F27-E27,"") -> -0.46 | J27: =IF(COUNT(E27,H27)=2,H27-E27,"") -> -0.22 | K27: =IF(COUNT(F27,G27)=2,F27-G27,"") | L27: 9 | M27: 9 | N27: 7 | O27: 1 | P27: 9 | Q27: 9 | R27: 9 | S27: 8 | T27: 9 | U27: 9 | V27: 9 | W27: 8 | X27: 8 | Y27: 9 | Z27: לא | AA27: בהליכה עם רצועה | AB27: 8 | AC27: 9 | AD27: 8 | AE27: 9 | AH27: =IF(COUNT(L27,P27)=2,P27-L27,"") -> 0 | AI27: =IF(COUNT(M27,Q27)=2,Q27-M27,"") -> 0 | AJ27: =IF(COUNT(N27,R27)=2,R27-N27,"") -> 2 | AK27: =IF(COUNT(O27,S27)=2,S27-O27,"") -> 7 | AL27: =IF(COUNT(AB27,AC27)=2,AC27-AB27,"") -> 1 | AM27: =IF(COUNT(AD27,AE27)=2,AE27-AD27,"") -> 1 | AN27: =IF(COUNT(F27,H27)=2,H27-F27,"") -> 0.24 | AO27: =IF(COUNT(E27,F27)=2,(F27-E27)/E27,"") -> -0.024704619 | AP27: =IF(COUNT(E27,H27)=2,(H27-E27)/E27,"") -> -0.011815252 | AQ27: =IF(COUNT(E27,G27)=2,(G27-E27)/E27,"")
A28: ABC | B28: 112 | C28: אישה | D28: BAC | E28: 16.37 | F28: 18.31 | H28: 18.44 | I28: =IF(COUNT(E28,F28)=2,F28-E28,"") -> 1.94 | J28: =IF(COUNT(E28,H28)=2,H28-E28,"") -> 2.07 | K28: =IF(COUNT(F28,G28)=2,F28-G28,"") | L28: 8 | M28: 9 | N28: 8 | O28: 2 | P28: 5 | Q28: 3 | R28: 4 | S28: 7 | T28: 5 | U28: 8 | V28: 7 | W28: 7 | X28: 7 | Y28: 8 | Z28: כן | AA28: בהליכה עם רצועה | AB28: 3 | AC28: 8 | AD28: 1 | AE28: 8 | AH28: =IF(COUNT(L28,P28)=2,P28-L28,"") -> -3 | AI28: =IF(COUNT(M28,Q28)=2,Q28-M28,"") -> -6 | AJ28: =IF(COUNT(N28,R28)=2,R28-N28,"") -> -4 | AK28: =IF(COUNT(O28,S28)=2,S28-O28,"") -> 5 | AL28: =IF(COUNT(AB28,AC28)=2,AC28-AB28,"") -> 5 | AM28: =IF(COUNT(AD28,AE28)=2,AE28-AD28,"") -> 7 | AN28: =IF(COUNT(F28,H28)=2,H28-F28,"") -> 0.13 | AO28: =IF(COUNT(E28,F28)=2,(F28-E28)/E28,"") -> 0.11850947 | AP28: =IF(COUNT(E28,H28)=2,(H28-E28)/E28,"") -> 0.12645082 | AQ28: =IF(COUNT(E28,G28)=2,(G28-E28)/E28,"")
A29: ABC | B29: 113 | C29: גבר | D29: CAB | E29: 20.34 | F29: 20.22 | H29: 26.68 | I29: =IF(COUNT(E29,F29)=2,F29-E29,"") -> -0.12 | J29: =IF(COUNT(E29,H29)=2,H29-E29,"") -> 6.34 | K29: =IF(COUNT(F29,G29)=2,F29-G29,"") | L29: 8 | M29: 7 | N29: 8 | O29: 1 | P29: 8 | Q29: 6 | R29: 8 | S29: 1 | T29: 7 | U29: 8 | V29: 6 | W29: 7 | X29: 3 | Y29: 3 | Z29: כן | AA29: בהליכה עם רצועה | AB29: 3 | AC29: 6 | AD29: 2 | AE29: 6 | AH29: =IF(COUNT(L29,P29)=2,P29-L29,"") -> 0 | AI29: =IF(COUNT(M29,Q29)=2,Q29-M29,"") -> -1 | AJ29: =IF(COUNT(N29,R29)=2,R29-N29,"") -> 0 | AK29: =IF(COUNT(O29,S29)=2,S29-O29,"") -> 0 | AL29: =IF(COUNT(AB29,AC29)=2,AC29-AB29,"") -> 3 | AM29: =IF(COUNT(AD29,AE29)=2,AE29-AD29,"") -> 4 | AN29: =IF(COUNT(F29,H29)=2,H29-F29,"") -> 6.46 | AO29: =IF(COUNT(E29,F29)=2,(F29-E29)/E29,"") -> -0.005899705 | AP29: =IF(COUNT(E29,H29)=2,(H29-E29)/E29,"") -> 0.31170108 | AQ29: =IF(COUNT(E29,G29)=2,(G29-E29)/E29,"")
A30: ABC | B30: 114 | C30: אישה | D30: BAC | E30: 15.5 | F30: 16.9 | H30: 19.5 | I30: =IF(COUNT(E30,F30)=2,F30-E30,"") -> 1.4 | J30: =IF(COUNT(E30,H30)=2,H30-E30,"") -> 4 | K30: =IF(COUNT(F30,G30)=2,F30-G30,"") | L30: 9 | M30: 9 | N30: 9 | O30: 2 | P30: 9 | Q30: 7 | R30: 7 | S30: 3 | T30: 5 | U30: 5 | V30: 7 | W30: 4 | X30: 7 | Y30: 6 | Z30: כן | AA30: בהליכה ללא רצועה | AB30: 6 | AC30: 5 | AD30: 7 | AE30: 6 | AH30: =IF(COUNT(L30,P30)=2,P30-L30,"") -> 0 | AI30: =IF(COUNT(M30,Q30)=2,Q30-M30,"") -> -2 | AJ30: =IF(COUNT(N30,R30)=2,R30-N30,"") -> -2 | AK30: =IF(COUNT(O30,S30)=2,S30-O30,"") -> 1 | AL30: =IF(COUNT(AB30,AC30)=2,AC30-AB30,"") -> -1 | AM30: =IF(COUNT(AD30,AE30)=2,AE30-AD30,"") -> -1 | AN30: =IF(COUNT(F30,H30)=2,H30-F30,"") -> 2.6 | AO30: =IF(COUNT(E30,F30)=2,(F30-E30)/E30,"") -> 0.090322581 | AP30: =IF(COUNT(E30,H30)=2,(H30-E30)/E30,"") -> 0.25806452 | AQ30: =IF(COUNT(E30,G30)=2,(G30-E30)/E30,"")
A31: ABC | B31: 115 | C31: אישה | D31: BAC | E31: 16.56 | F31: 17.28 | H31: 21.75 | I31: =IF(COUNT(E31,F31)=2,F31-E31,"") -> 0.72 | J31: =IF(COUNT(E31,H31)=2,H31-E31,"") -> 5.19 | K31: =IF(COUNT(F31,G31)=2,F31-G31,"") | L31: 9 | M31: 9 | N31: 9 | O31: 1 | P31: 8 | Q31: 7 | R31: 9 | S31: 1 | T31: 5 | U31: 8 | V31: 8 | W31: 8 | X31: 5 | Y31: 7 | Z31: כן | AA31: בהליכה עם רצועה | AB31: 7 | AC31: 8 | AD31: 9 | AE31: 8 | AH31: =IF(COUNT(L31,P31)=2,P31-L31,"") -> -1 | AI31: =IF(COUNT(M31,Q31)=2,Q31-M31,"") -> -2 | AJ31: =IF(COUNT(N31,R31)=2,R31-N31,"") -> 0 | AK31: =IF(COUNT(O31,S31)=2,S31-O31,"") -> 0 | AL31: =IF(COUNT(AB31,AC31)=2,AC31-AB31,"") -> 1 | AM31: =IF(COUNT(AD31,AE31)=2,AE31-AD31,"") -> -1 | AN31: =IF(COUNT(F31,H31)=2,H31-F31,"") -> 4.47 | AO31: =IF(COUNT(E31,F31)=2,(F31-E31)/E31,"") -> 0.043478261 | AP31: =IF(COUNT(E31,H31)=2,(H31-E31)/E31,"") -> 0.3134058 | AQ31: =IF(COUNT(E31,G31)=2,(G31-E31)/E31,"")
A32: ABC | B32: 116 | C32: גבר | D32: ABC | E32: 18.81 | F32: 20.5 | H32: 19.15 | I32: =IF(COUNT(E32,F32)=2,F32-E32,"") -> 1.69 | J32: =IF(COUNT(E32,H32)=2,H32-E32,"") -> 0.34 | K32: =IF(COUNT(F32,G32)=2,F32-G32,"") | L32: 5 | M32: 9 | N32: 5 | O32: 2 | P32: 5 | Q32: 9 | R32: 5 | S32: 2 | T32: 8 | U32: 7 | V32: 9 | W32: 7 | X32: 2 | Y32: 9 | Z32: לא | AA32: בהליכה עם רצועה | AB32: 8 | AC32: 9 | AD32: 3 | AE32: 5 | AH32: =IF(COUNT(L32,P32)=2,P32-L32,"") -> 0 | AI32: =IF(COUNT(M32,Q32)=2,Q32-M32,"") -> 0 | AJ32: =IF(COUNT(N32,R32)=2,R32-N32,"") -> 0 | AK32: =IF(COUNT(O32,S32)=2,S32-O32,"") -> 0 | AL32: =IF(COUNT(AB32,AC32)=2,AC32-AB32,"") -> 1 | AM32: =IF(COUNT(AD32,AE32)=2,AE32-AD32,"") -> 2 | AN32: =IF(COUNT(F32,H32)=2,H32-F32,"") -> -1.35 | AO32: =IF(COUNT(E32,F32)=2,(F32-E32)/E32,"") -> 0.089845827 | AP32: =IF(COUNT(E32,H32)=2,(H32-E32)/E32,"") -> 0.018075492 | AQ32: =IF(COUNT(E32,G32)=2,(G32-E32)/E32,"")
A33: ABC | B33: 117 | C33: אישה | D33: CBA | E33: 16.78 | F33: 16.44 | H33: 17.1 | I33: =IF(COUNT(E33,F33)=2,F33-E33,"") -> -0.34 | J33: =IF(COUNT(E33,H33)=2,H33-E33,"") -> 0.32 | K33: =IF(COUNT(F33,G33)=2,F33-G33,"") | L33: 8 | M33: 8 | N33: 8 | O33: 1 | P33: 8 | Q33: 8 | R33: 8 | S33: 2 | T33: 8 | U33: 7 | V33: 6 | W33: 6 | X33: 3 | Y33: 7 | Z33: לא | AA33: לא הרגשתי הבדל בין המצבים | AB33: 8 | AC33: 6 | AD33: 6 | AE33: 6 | AH33: =IF(COUNT(L33,P33)=2,P33-L33,"") -> 0 | AI33: =IF(COUNT(M33,Q33)=2,Q33-M33,"") -> 0 | AJ33: =IF(COUNT(N33,R33)=2,R33-N33,"") -> 0 | AK33: =IF(COUNT(O33,S33)=2,S33-O33,"") -> 1 | AL33: =IF(COUNT(AB33,AC33)=2,AC33-AB33,"") -> -2 | AM33: =IF(COUNT(AD33,AE33)=2,AE33-AD33,"") -> 0 | AN33: =IF(COUNT(F33,H33)=2,H33-F33,"") -> 0.66 | AO33: =IF(COUNT(E33,F33)=2,(F33-E33)/E33,"") -> -0.020262217 | AP33: =IF(COUNT(E33,H33)=2,(H33-E33)/E33,"") -> 0.019070322 | AQ33: =IF(COUNT(E33,G33)=2,(G33-E33)/E33,"")
... A37: ABC | B37: 121 | C37: גבר | D37: ABC | E37: 14.9 | F37: 17.69 | H37: 16.66 | I37: =IF(COUNT(E37,F37)=2,F37-E37,"") -> 2.79 | J37: =IF(COUNT(E37,H37)=2,H37-E37,"") -> 1.76 | K37: =IF(COUNT(F37,G37)=2,F37-G37,"") | L37: 8 | M37: 8 | N37: 8 | O37: 1 | P37: 8 | Q37: 7 | R37: 8 | S37: 1 | T37: 6 | U37: 8 | V37: 8 | W37: 8 | X37: 1 | Y37: 8 | Z37: כן | AA37: בהליכה עם רצועה | AB37: 6 | AC37: 8 | AD37: 5 | AE37: 7 | AH37: =IF(COUNT(L37,P37)=2,P37-L37,"") -> 0 | AI37: =IF(COUNT(M37,Q37)=2,Q37-M37,"") -> -1 | AJ37: =IF(COUNT(N37,R37)=2,R37-N37,"") -> 0 | AK37: =IF(COUNT(O37,S37)=2,S37-O37,"") -> 0 | AL37: =IF(COUNT(AB37,AC37)=2,AC37-AB37,"") -> 2 | AM37: =IF(COUNT(AD37,AE37)=2,AE37-AD37,"") -> 2 | AN37: =IF(COUNT(F37,H37)=2,H37-F37,"") -> -1.03 | AO37: =IF(COUNT(E37,F37)=2,(F37-E37)/E37,"") -> 0.18724832 | AP37: =IF(COUNT(E37,H37)=2,(H37-E37)/E37,"") -> 0.11812081 | AQ37: =IF(COUNT(E37,G37)=2,(G37-E37)/E37,"")
A38: ABC | B38: 122 | C38: גבר | D38: ACB | E38: 13.28 | F38: 13.94 | H38: 14.56 | I38: =IF(COUNT(E38,F38)=2,F38-E38,"") -> 0.66 | J38: =IF(COUNT(E38,H38)=2,H38-E38,"") -> 1.28 | K38: =IF(COUNT(F38,G38)=2,F38-G38,"") | L38: 9 | M38: 9 | N38: 9 | O38: 1 | P38: 9 | Q38: 9 | R38: 9 | S38: 1 | T38: 9 | U38: 8 | V38: 9 | W38: 9 | X38: 8 | Y38: 7 | Z38: לא | AA38: לא הרגשתי הבדל בין המצבים | AB38: 9 | AC38: 9 | AD38: 8 | AE38: 8 | AF38: 8 | AG38: 5 | AH38: =IF(COUNT(L38,P38)=2,P38-L38,"") -> 0 | AI38: =IF(COUNT(M38,Q38)=2,Q38-M38,"") -> 0 | AJ38: =IF(COUNT(N38,R38)=2,R38-N38,"") -> 0 | AK38: =IF(COUNT(O38,S38)=2,S38-O38,"") -> 0 | AL38: =IF(COUNT(AB38,AC38)=2,AC38-AB38,"") -> 0 | AM38: =IF(COUNT(AD38,AE38)=2,AE38-AD38,"") -> 0 | AN38: =IF(COUNT(F38,H38)=2,H38-F38,"") -> 0.62 | AO38: =IF(COUNT(E38,F38)=2,(F38-E38)/E38,"") -> 0.049698795 | AP38: =IF(COUNT(E38,H38)=2,(H38-E38)/E38,"") -> 0.096385542 | AQ38: =IF(COUNT(E38,G38)=2,(G38-E38)/E38,"")
A39: ABC | B39: 123 | C39: אישה | D39: ACB | E39: 14.06 | F39: 13.87 | H39: 15.9 | I39: =IF(COUNT(E39,F39)=2,F39-E39,"") -> -0.19 | J39: =IF(COUNT(E39,H39)=2,H39-E39,"") -> 1.84 | K39: =IF(COUNT(F39,G39)=2,F39-G39,"") | L39: 6 | M39: 6 | N39: 9 | O39: 1 | P39: 6 | Q39: 6 | R39: 6 | S39: 6 | T39: 1 | U39: 3 | V39: 3 | W39: 9 | X39: 1 | Y39: 1 | Z39: כן | AA39: אף פעם לא הרגשתי שהוא שותף להליכה | AB39: 4 | AC39: 4 | AD39: 3 | AE39: 3 | AF39: 1 | AG39: 1 | AH39: =IF(COUNT(L39,P39)=2,P39-L39,"") -> 0 | AI39: =IF(COUNT(M39,Q39)=2,Q39-M39,"") -> 0 | AJ39: =IF(COUNT(N39,R39)=2,R39-N39,"") -> -3 | AK39: =IF(COUNT(O39,S39)=2,S39-O39,"") -> 5 | AL39: =IF(COUNT(AB39,AC39)=2,AC39-AB39,"") -> 0 | AM39: =IF(COUNT(AD39,AE39)=2,AE39-AD39,"") -> 0 | AN39: =IF(COUNT(F39,H39)=2,H39-F39,"") -> 2.03 | AO39: =IF(COUNT(E39,F39)=2,(F39-E39)/E39,"") -> -0.013513514 | AP39: =IF(COUNT(E39,H39)=2,(H39-E39)/E39,"") -> 0.13086771 | AQ39: =IF(COUNT(E39,G39)=2,(G39-E39)/E39,"")
A40: ABC | B40: 124 | C40: אישה | D40: BAC | E40: 15.26 | F40: 21.15 | H40: 18.78 | I40: =IF(COUNT(E40,F40)=2,F40-E40,"") -> 5.89 | J40: =IF(COUNT(E40,H40)=2,H40-E40,"") -> 3.52 | K40: =IF(COUNT(F40,G40)=2,F40-G40,"") | L40: 9 | M40: 9 | N40: 9 | O40: 2 | P40: 3 | Q40: 8 | R40: 3 | S40: 8 | T40: 6 | U40: 7 | V40: 6 | W40: 7 | X40: 4 | Y40: 4 | Z40: כן | AA40: אף פעם לא הרגשתי שהוא שותף להליכה | AB40: 4 | AC40: 6 | AD40: 4 | AE40: 7 | AF40: 2 | AG40: 2 | AH40: =IF(COUNT(L40,P40)=2,P40-L40,"") -> -6 | AI40: =IF(COUNT(M40,Q40)=2,Q40-M40,"") -> -1 | AJ40: =IF(COUNT(N40,R40)=2,R40-N40,"") -> -6 | AK40: =IF(COUNT(O40,S40)=2,S40-O40,"") -> 6 | AL40: =IF(COUNT(AB40,AC40)=2,AC40-AB40,"") -> 2 | AM40: =IF(COUNT(AD40,AE40)=2,AE40-AD40,"") -> 3 | AN40: =IF(COUNT(F40,H40)=2,H40-F40,"") -> -2.37 | AO40: =IF(COUNT(E40,F40)=2,(F40-E40)/E40,"") -> 0.38597641 | AP40: =IF(COUNT(E40,H40)=2,(H40-E40)/E40,"") -> 0.23066841 | AQ40: =IF(COUNT(E40,G40)=2,(G40-E40)/E40,"")
A41: ABC | B41: 125 | C41: גבר | D41: BCA | E41: 11.66 | F41: 14.04 | H41: 13.22 | I41: =IF(COUNT(E41,F41)=2,F41-E41,"") -> 2.38 | J41: =IF(COUNT(E41,H41)=2,H41-E41,"") -> 1.56 | K41: =IF(COUNT(F41,G41)=2,F41-G41,"") | L41: 9 | M41: 9 | N41: 8 | O41: 1 | P41: 9 | Q41: 9 | R41: 8 | S41: 2 | T41: 8 | U41: 7 | V41: 8 | W41: 7 | X41: 5 | Y41: 7 | Z41: לא | AA41: בהליכה עם רצועה | AB41: 9 | AC41: 7 | AD41: 9 | AE41: 7 | AF41: 8 | AG41: 6 | AH41: =IF(COUNT(L41,P41)=2,P41-L41,"") -> 0 | AI41: =IF(COUNT(M41,Q41)=2,Q41-M41,"") -> 0 | AJ41: =IF(COUNT(N41,R41)=2,R41-N41,"") -> 0 | AK41: =IF(COUNT(O41,S41)=2,S41-O41,"") -> 1 | AL41: =IF(COUNT(AB41,AC41)=2,AC41-AB41,"") -> -2 | AM41: =IF(COUNT(AD41,AE41)=2,AE41-AD41,"") -> -2 | AN41: =IF(COUNT(F41,H41)=2,H41-F41,"") -> -0.82 | AO41: =IF(COUNT(E41,F41)=2,(F41-E41)/E41,"") -> 0.20411664 | AP41: =IF(COUNT(E41,H41)=2,(H41-E41)/E41,"") -> 0.13379074 | AQ41: =IF(COUNT(E41,G41)=2,(G41-E41)/E41,"")
A42: ABC | B42: 126 | C42: אישה | D42: CAB | E42: 14.63 | F42: 13.63 | H42: 16.24 | I42: =IF(COUNT(E42,F42)=2,F42-E42,"") -> -1 | J42: =IF(COUNT(E42,H42)=2,H42-E42,"") -> 1.61 | K42: =IF(COUNT(F42,G42)=2,F42-G42,"") | L42: 9 | M42: 9 | N42: 9 | O42: 1 | P42: 8 | Q42: 5 | R42: 6 | S42: 4 | T42: 6 | U42: 6 | V42: 6 | W42: 6.5 | X42: 7 | Y42: 6 | Z42: כן | AA42: בהליכה עם רצועה | AB42: 4 | AC42: 7 | AD42: 3 | AE42: 7 | AF42: 7 | AG42: 2 | AH42: =IF(COUNT(L42,P42)=2,P42-L42,"") -> -1 | AI42: =IF(COUNT(M42,Q42)=2,Q42-M42,"") -> -4 | AJ42: =IF(COUNT(N42,R42)=2,R42-N42,"") -> -3 | AK42: =IF(COUNT(O42,S42)=2,S42-O42,"") -> 3 | AL42: =IF(COUNT(AB42,AC42)=2,AC42-AB42,"") -> 3 | AM42: =IF(COUNT(AD42,AE42)=2,AE42-AD42,"") -> 4 | AN42: =IF(COUNT(F42,H42)=2,H42-F42,"") -> 2.61 | AO42: =IF(COUNT(E42,F42)=2,(F42-E42)/E42,"") -> -0.0683527 | AP42: =IF(COUNT(E42,H42)=2,(H42-E42)/E42,"") -> 0.11004785 | AQ42: =IF(COUNT(E42,G42)=2,(G42-E42)/E42,"")
A43: ABC | B43: 127 | C43: גבר | D43: CBA | E43: 13.85 | F43: 18.34 | H43: 17.5 | I43: =IF(COUNT(E43,F43)=2,F43-E43,"") -> 4.49 | J43: =IF(COUNT(E43,H43)=2,H43-E43,"") -> 3.65 | K43: =IF(COUNT(F43,G43)=2,F43-G43,"") | L43: 9 | M43: 9 | N43: 9 | O43: 1 | P43: 6 | Q43: 8 | R43: 6 | S43: 7 | T43: 7 | U43: 6 | V43: 8 | W43: 5 | X43: 9 | Y43: 7 | Z43: כן | AA43: לא הרגשתי הבדל בין המצבים | AB43: 5 | AC43: 6 | AD43: 2 | AE43: 4 | AF43: 8 | AG43: 3 | AH43: =IF(COUNT(L43,P43)=2,P43-L43,"") -> -3 | AI43: =IF(COUNT(M43,Q43)=2,Q43-M43,"") -> -1 | AJ43: =IF(COUNT(N43,R43)=2,R43-N43,"") -> -3 | AK43: =IF(COUNT(O43,S43)=2,S43-O43,"") -> 6 | AL43: =IF(COUNT(AB43,AC43)=2,AC43-AB43,"") -> 1 | AM43: =IF(COUNT(AD43,AE43)=2,AE43-AD43,"") -> 2 | AN43: =IF(COUNT(F43,H43)=2,H43-F43,"") -> -0.84 | AO43: =IF(COUNT(E43,F43)=2,(F43-E43)/E43,"") -> 0.32418773 | AP43: =IF(COUNT(E43,H43)=2,(H43-E43)/E43,"") -> 0.26353791 | AQ43: =IF(COUNT(E43,G43)=2,(G43-E43)/E43,"")
A44: ABC | B44: 128 | C44: אישה | D44: BAC | E44: 15.85 | F44: 25.59 | H44: 15.25 | I44: =IF(COUNT(E44,F44)=2,F44-E44,"") -> 9.74 | J44: =IF(COUNT(E44,H44)=2,H44-E44,"") -> -0.6 | K44: =IF(COUNT(F44,G44)=2,F44-G44,"") | L44: 9 | M44: 9 | N44: 8 | O44: 6 | P44: 9 | Q44: 7 | R44: 7 | S44: 7 | T44: 7 | U44: 9 | V44: 8 | W44: 6 | X44: 3 | Y44: 9 | Z44: לא | AA44: בהליכה עם רצועה | AB44: 8 | AC44: 9 | AD44: 2 | AE44: 5 | AF44: 9 | AG44: 6 | AH44: =IF(COUNT(L44,P44)=2,P44-L44,"") -> 0 | AI44: =IF(COUNT(M44,Q44)=2,Q44-M44,"") -> -2 | AJ44: =IF(COUNT(N44,R44)=2,R44-N44,"") -> -1 | AK44: =IF(COUNT(O44,S44)=2,S44-O44,"") -> 1 | AL44: =IF(COUNT(AB44,AC44)=2,AC44-AB44,"") -> 1 | AM44: =IF(COUNT(AD44,AE44)=2,AE44-AD44,"") -> 3 | AN44: =IF(COUNT(F44,H44)=2,H44-F44,"") -> -10.34 | AO44: =IF(COUNT(E44,F44)=2,(F44-E44)/E44,"") -> 0.61451104 | AP44: =IF(COUNT(E44,H44)=2,(H44-E44)/E44,"") -> -0.03785489 | AQ44: =IF(COUNT(E44,G44)=2,(G44-E44)/E44,"")
A45: ABC | B45: 129 | C45: גבר | D45: BCA | E45: 15.28 | F45: 17.91 | H45: 19 | I45: =IF(COUNT(E45,F45)=2,F45-E45,"") -> 2.63 | J45: =IF(COUNT(E45,H45)=2,H45-E45,"") -> 3.72 | K45: =IF(COUNT(F45,G45)=2,F45-G45,"") | L45: 8 | M45: 7 | N45: 8 | O45: 1 | P45: 7 | Q45: 6 | R45: 9 | S45: 1 | T45: 7 | U45: 7 | V45: 8 | W45: 6 | X45: 6 | Y45: 7 | Z45: לא | AA45: בהליכה ללא רצועה | AB45: 6 | AC45: 7 | AD45: 6 | AE45: 7 | AF45: 4 | AG45: 4 | AH45: =IF(COUNT(L45,P45)=2,P45-L45,"") -> -1 | AI45: =IF(COUNT(M45,Q45)=2,Q45-M45,"") -> -1 | AJ45: =IF(COUNT(N45,R45)=2,R45-N45,"") -> 1 | AK45: =IF(COUNT(O45,S45)=2,S45-O45,"") -> 0 | AL45: =IF(COUNT(AB45,AC45)=2,AC45-AB45,"") -> 1 | AM45: =IF(COUNT(AD45,AE45)=2,AE45-AD45,"") -> 1 | AN45: =IF(COUNT(F45,H45)=2,H45-F45,"") -> 1.09 | AO45: =IF(COUNT(E45,F45)=2,(F45-E45)/E45,"") -> 0.17212042 | AP45: =IF(COUNT(E45,H45)=2,(H45-E45)/E45,"") -> 0.2434555 | AQ45: =IF(COUNT(E45,G45)=2,(G45-E45)/E45,"")
A46: ABC | B46: 130 | C46: גבר | D46: CAB | E46: 16.65 | F46: 18.5 | H46: 18.91 | I46: =IF(COUNT(E46,F46)=2,F46-E46,"") -> 1.85 | J46: =IF(COUNT(E46,H46)=2,H46-E46,"") -> 2.26 | K46: =IF(COUNT(F46,G46)=2,F46-G46,"") | L46: 9 | M46: 9 | N46: 9 | O46: 1 | P46: 7 | Q46: 4 | R46: 6 | S46: 8 | T46: 6 | U46: 8 | V46: 9 | W46: 9 | X46: 6 | Y46: 8 | Z46: כן | AA46: בהליכה עם רצועה | AB46: 5 | AC46: 8 | AD46: 4 | AE46: 7 | AF46: 7 | AG46: 4 | AH46: =IF(COUNT(L46,P46)=2,P46-L46,"") -> -2 | AI46: =IF(COUNT(M46,Q46)=2,Q46-M46,"") -> -5 | AJ46: =IF(COUNT(N46,R46)=2,R46-N46,"") -> -3 | AK46: =IF(COUNT(O46,S46)=2,S46-O46,"") -> 7 | AL46: =IF(COUNT(AB46,AC46)=2,AC46-AB46,"") -> 3 | AM46: =IF(COUNT(AD46,AE46)=2,AE46-AD46,"") -> 3 | AN46: =IF(COUNT(F46,H46)=2,H46-F46,"") -> 0.41 | AO46: =IF(COUNT(E46,F46)=2,(F46-E46)/E46,"") -> 0.11111111 | AP46: =IF(COUNT(E46,H46)=2,(H46-E46)/E46,"") -> 0.13573574 | AQ46: =IF(COUNT(E46,G46)=2,(G46-E46)/E46,"")
A47: ABC | B47: 131 | C47: אישה | D47: CBA | E47: 13.19 | F47: 14.44 | H47: 15.12 | I47: =IF(COUNT(E47,F47)=2,F47-E47,"") -> 1.25 | J47: =IF(COUNT(E47,H47)=2,H47-E47,"") -> 1.93 | K47: =IF(COUNT(F47,G47)=2,F47-G47,"") | L47: 9 | M47: 9 | N47: 8 | O47: 1 | P47: 7 | Q47: 9 | R47: 9 | S47: 3 | T47: 9 | U47: 4 | V47: 6 | W47: 4 | X47: 7 | Y47: 9 | Z47: לא | AA47: בהליכה ללא רצועה | AB47: 9 | AC47: 7 | AD47: 9 | AE47: 6 | AF47: 9 | AG47: 5 | AH47: =IF(COUNT(L47,P47)=2,P47-L47,"") -> -2 | AI47: =IF(COUNT(M47,Q47)=2,Q47-M47,"") -> 0 | AJ47: =IF(COUNT(N47,R47)=2,R47-N47,"") -> 1 | AK47: =IF(COUNT(O47,S47)=2,S47-O47,"") -> 2 | AL47: =IF(COUNT(AB47,AC47)=2,AC47-AB47,"") -> -2 | AM47: =IF(COUNT(AD47,AE47)=2,AE47-AD47,"") -> -3 | AN47: =IF(COUNT(F47,H47)=2,H47-F47,"") -> 0.68 | AO47: =IF(COUNT(E47,F47)=2,(F47-E47)/E47,"") -> 0.094768764 | AP47: =IF(COUNT(E47,H47)=2,(H47-E47)/E47,"") -> 0.14632297 | AQ47: =IF(COUNT(E47,G47)=2,(G47-E47)/E47,"")
...

Sheet ניתוח חי — זמנים
B1: ניתוח חי — זמני הליכה
B2: כל הערכים מחושבים בנוסחאות אקסל מתוך גיליון 'טבלת אב'. שינוי כל נתון שם יעדכן את כל המספרים כאן אוטומטית. מבחני t מזווגים ומתאמים הם פרמטריים (המקבילה של אקסל למבחנים הלא-פרמטריים בגיליונות הנרטיב). ה־N משתנה בין השוואה להשוואה מפני שכל מבחן מזווג כולל רק נסיינים שיש להם שני הערכים הרלוונטיים.
B4: ① טבלת השוואה מרכזית (שניות)
B5: מדד | C5: A — לבד | D5: B — כלב | E5: C — רצועה | F5: B2 — כלב#2
B6: ממוצע | C6: =AVERAGE('טבלת אב'!E2:E98) -> 15.491753 | D6: =AVERAGE('טבלת אב'!F2:F98) -> 17.234149 | E6: =AVERAGE('טבלת אב'!H2:H98) -> 17.316842 | F6: =AVERAGE('טבלת אב'!G2:G98) -> 16.278947
B7: חציון | C7: =MEDIAN('טבלת אב'!E2:E98) -> 15.31 | D7: =MEDIAN('טבלת אב'!F2:F98) -> 17 | E7: =MEDIAN('טבלת אב'!H2:H98) -> 17.16 | F7: =MEDIAN('טבלת אב'!G2:G98) -> 16.25
B8: סטיית תקן | C8: =STDEV('טבלת אב'!E2:E98) -> 2.2284136 | D8: =STDEV('טבלת אב'!F2:F98) -> 2.9104644 | E8: =STDEV('טבלת אב'!H2:H98) -> 2.7815397 | F8: =STDEV('טבלת אב'!G2:G98) -> 2.1736781
B9: מינימום | C9: =MIN('טבלת אב'!E2:E98) -> 11.19 | D9: =MIN('טבלת אב'!F2:F98) -> 12.97 | E9: =MIN('טבלת אב'!H2:H98) -> 12.28 | F9: =MIN('טבלת אב'!G2:G98) -> 12.16
B10: מקסימום | C10: =MAX('טבלת אב'!E2:E98) -> 22.16 | D10: =MAX('טבלת אב'!F2:F98) -> 29.47 | E10: =MAX('טבלת אב'!H2:H98) -> 26.68 | F10: =MAX('טבלת אב'!G2:G98) -> 20.94
B11: N (נסיינים) | C11: =COUNT('טבלת אב'!E2:E98) -> 97 | D11: =COUNT('טבלת אב'!F2:F98) -> 94 | E11: =COUNT('טבלת אב'!H2:H98) -> 76 | F11: =COUNT('טבלת אב'!G2:G98) -> 19
B13: ② השפעת הכלב — לבד מול כלב בלי רצועה (B−A)
B14: הפרש ממוצע (שנ') | C14: =AVERAGE('טבלת אב'!I2:I98) -> 1.7742553
B15: % שהואטו (הפרש>0) | C15: =COUNTIF('טבלת אב'!I2:I98,">0")/COUNT('טבלת אב'!I2:I98) -> 0.78723404
B16: t (מבחן t מזווג) | C16: =AVERAGE('טבלת אב'!I2:I98)/(STDEV('טבלת אב'!I2:I98)/SQRT(COUNT('טבלת אב'!I2:I98))) -> 7.7549844
B17: p-value | C17: =TDIST(MAX(ABS(C16),0.000000001),COUNT('טבלת אב'!I2:I98)-1,2) -> 1.097867e-11
B18: N (זוגות) | C18: =COUNT('טבלת אב'!I2:I98) -> 94
B20: ③ השפעת הכלב עם רצועה — לבד מול C (C−A)
B21: הפרש ממוצע (שנ') | C21: =AVERAGE('טבלת אב'!J2:J98) -> 1.7821053
B22: % שהואטו (הפרש>0) | C22: =COUNTIF('טבלת אב'!J2:J98,">0")/COUNT('טבלת אב'!J2:J98) -> 0.88157895
B23: t (מבחן t מזווג) | C23: =AVERAGE('טבלת אב'!J2:J98)/(STDEV('טבלת אב'!J2:J98)/SQRT(COUNT('טבלת אב'!J2:J98))) -> 8.5141292
B24: p-value | C24: =TDIST(MAX(ABS(C23),0.000000001),COUNT('טבלת אב'!J2:J98)-1,2) -> 1.2522878e-12
B25: N (זוגות) | C25: =COUNT('טבלת אב'!J2:J98) -> 76
B27: ④ רצועה מול בלי רצועה (C−B)
B28: הפרש ממוצע (שנ') | C28: =AVERAGE('טבלת אב'!AN2:AN98) -> 0.17123288
B29: % איטי יותר עם רצועה | C29: =COUNTIF('טבלת אב'!AN2:AN98,">0")/COUNT('טבלת אב'!AN2:AN98) -> 0.5890411
B30: t (מבחן t מזווג) | C30: =AVERAGE('טבלת אב'!AN2:AN98)/(STDEV('טבלת אב'!AN2:AN98)/SQRT(COUNT('טבלת אב'!AN2:AN98))) -> 0.58221681
B31: p-value | C31: =TDIST(MAX(ABS(C30),0.000000001),COUNT('טבלת אב'!AN2:AN98)-1,2) -> 0.56223942
B32: N (זוגות) | C32: =COUNT('טבלת אב'!AN2:AN98) -> 73
B34: ⑤ התרגלות — הליכת כלב 1 מול 2 (B1−B2)
B35: הפרש ממוצע (שנ') | C35: =AVERAGE('טבלת אב'!K2:K98) -> 0.84157895
B36: % שהשתפרו (הפרש>0) | C36: =COUNTIF('טבלת אב'!K2:K98,">0")/COUNT('טבלת אב'!K2:K98) -> 0.68421053
B37: t (מבחן t מזווג) | C37: =AVERAGE('טבלת אב'!K2:K98)/(STDEV('טבלת אב'!K2:K98)/SQRT(COUNT('טבלת אב'!K2:K98))) -> 2.8514832
B38: p-value | C38: =TDIST(MAX(ABS(C37),0.000000001),COUNT('טבלת אב'!K2:K98)-1,2) -> 0.010597869
B39: N (זוגות) | C39: =COUNT('טבלת אב'!K2:K98) -> 19
B41: ⑥ פילוח לפי מקור ומגדר
B42: ממוצע A — ניסוי ABC | C42: =AVERAGEIF('טבלת אב'!A2:A98,"ABC",'טבלת אב'!E2:E98) -> 15.533506
B43: ממוצע A — ניסוי ABB | C43: =AVERAGEIF('טבלת אב'!A2:A98,"ABB",'טבלת אב'!E2:E98) -> 15.331
B44: ממוצע B — ניסוי ABC | C44: =AVERAGEIF('טבלת אב'!A2:A98,"ABC",'טבלת אב'!F2:F98) -> 17.143514
B45: ממוצע B — ניסוי ABB | C45: =AVERAGEIF('טבלת אב'!A2:A98,"ABB",'טבלת אב'!F2:F98) -> 17.5695
B46: האטה B−A — גברים | C46: =AVERAGEIF('טבלת אב'!C2:C98,"גבר",'טבלת אב'!I2:I98) -> 1.8747368
...

Sheet ניתוח חי — שאלונים
B1: ניתוח חי — שאלונים
B2: סולם 1–9. כל המספרים נוסחאות חיות מתוך 'טבלת אב'.
B4: ① חוויה סובייקטיבית לפי תנאי
B5: היגד | C5: לבד (A) | D5: כלב (B) | E5: רצועה (C)
B6: הרגיש טבעי | C6: =AVERAGE('טבלת אב'!L2:L98) -> 8.4895833 | D6: =AVERAGE('טבלת אב'!P2:P98) -> 7.5206186 | E6: =AVERAGE('טבלת אב'!U2:U98) -> 7.3733333
B7: הרגשתי בטוח | C7: =AVERAGE('טבלת אב'!M2:M98) -> 8.6875 | D7: =AVERAGE('טבלת אב'!Q2:Q98) -> 7.4948454 | E7: =AVERAGE('טבלת אב'!V2:V98) -> 7.68
B8: שמרתי על הקצב | C8: =AVERAGE('טבלת אב'!N2:N98) -> 8.5104167 | D8: =AVERAGE('טבלת אב'!R2:R98) -> 7.4587629 | E8: =AVERAGE('טבלת אב'!W2:W98) -> 7.4066667
B9: צורך לשנות קצב | C9: =AVERAGE('טבלת אב'!O2:O98) -> 1.9791667 | D9: =AVERAGE('טבלת אב'!S2:S98) -> 3.4948454 | E9: =AVERAGE('טבלת אב'!X2:X98) -> 4.2666667
B11: ② השפעת הכלב על החוויה (A מול B, מבחן t מזווג)
B12: היגד | C12: הפרש B−A | D12: t | E12: p-value
B13: הרגיש טבעי | C13: =AVERAGE('טבלת אב'!AH2:AH98) -> -0.984375 | D13: =AVERAGE('טבלת אב'!AH2:AH98)/(STDEV('טבלת אב'!AH2:AH98)/SQRT(COUNT('טבלת אב'!AH2:AH98))) -> -5.718656 | E13: =TDIST(MAX(ABS(D13),0.000000001),COUNT('טבלת אב'!AH2:AH98)-1,2) -> 1.2384775e-07
B14: הרגשתי בטוח | C14: =AVERAGE('טבלת אב'!AI2:AI98) -> -1.2083333 | D14: =AVERAGE('טבלת אב'!AI2:AI98)/(STDEV('טבלת אב'!AI2:AI98)/SQRT(COUNT('טבלת אב'!AI2:AI98))) -> -7.1042681 | E14: =TDIST(MAX(ABS(D14),0.000000001),COUNT('טבלת אב'!AI2:AI98)-1,2) -> 2.2069219e-10
B15: שמרתי על הקצב | C15: =AVERAGE('טבלת אב'!AJ2:AJ98) -> -1.0677083 | D15: =AVERAGE('טבלת אב'!AJ2:AJ98)/(STDEV('טבלת אב'!AJ2:AJ98)/SQRT(COUNT('טבלת אב'!AJ2:AJ98))) -> -5.6188529 | E15: =TDIST(MAX(ABS(D15),0.000000001),COUNT('טבלת אב'!AJ2:AJ98)-1,2) -> 1.9133393e-07
B16: צורך לשנות קצב | C16: =AVERAGE('טבלת אב'!AK2:AK98) -> 1.5416667 | D16: =AVERAGE('טבלת אב'!AK2:AK98)/(STDEV('טבלת אב'!AK2:AK98)/SQRT(COUNT('טבלת אב'!AK2:AK98))) -> 5.2519753 | E16: =TDIST(MAX(ABS(D16),0.000000001),COUNT('טבלת אב'!AK2:AK98)-1,2) -> 9.1823672e-07
B18: ③ פרדוקס הרצועה (מתוך שאלון סיכום)
B19: ביטחון — בלי רצועה | C19: =AVERAGE('טבלת אב'!AB2:AB98) -> 7.0131579
B20: ביטחון — עם רצועה | C20: =AVERAGE('טבלת אב'!AC2:AC98) -> 7.3684211
B21: t (ביטחון בלי מול עם) | C21: =AVERAGE('טבלת אב'!AL2:AL98)/(STDEV('טבלת אב'!AL2:AL98)/SQRT(COUNT('טבלת אב'!AL2:AL98))) -> 1.6983707
B22: p-value (ביטחון) | C22: =TDIST(MAX(ABS(C21),0.000000001),COUNT('טבלת אב'!AL2:AL98)-1,2) -> 0.093583157
B23: שליטה — בלי רצועה | C23: =AVERAGE('טבלת אב'!AD2:AD98) -> 6.0131579
B24: שליטה — עם רצועה | C24: =AVERAGE('טבלת אב'!AE2:AE98) -> 6.7894737
B25: t (שליטה בלי מול עם) | C25: =AVERAGE('טבלת אב'!AM2:AM98)/(STDEV('טבלת אב'!AM2:AM98)/SQRT(COUNT('טבלת אב'!AM2:AM98))) -> 3.0839232
B26: p-value (שליטה) | C26: =TDIST(MAX(ABS(C25),0.000000001),COUNT('טבלת אב'!AM2:AM98)-1,2) -> 0.002859137
B28: ④ 'שותף' מול 'מכשיר' — ספירת תשובות
B29: חשו שותף — עם רצועה | C29: =COUNTIF('טבלת אב'!AA2:AA98,"בהליכה עם רצועה") -> 42
B30: חשו שותף — בלי רצועה | C30: =COUNTIF('טבלת אב'!AA2:AA98,"בהליכה ללא רצועה") -> 17
B31: לא הרגישו הבדל | C31: =COUNTIF('טבלת אב'!AA2:AA98,"לא הרגשתי הבדל בין המצבים") -> 12
B32: אף פעם לא שותף | C32: =COUNTIF('טבלת אב'!AA2:AA98,"אף פעם לא הרגשתי שהוא שותף להליכה") -> 5
B34: ⑤ קישור: דירוג סובייקטיבי מול האטה בפועל (מתאם)
B35: מתאם פירסון בין ההאטה האובייקטיבית (B−A) לבין הדירוג בשאלון B. שלילי = דירוג גבוה קשור להאטה קטנה.
B36: 'שמרתי על הקצב' מול האטה | C36: =CORREL('טבלת אב'!I2:I98,'טבלת אב'!R2:R98) -> -0.42859686
B37: 'הרגיש טבעי' מול האטה | C37: =CORREL('טבלת אב'!I2:I98,'טבלת אב'!P2:P98) -> -0.30267737
B38: 'צורך לשנות' מול האטה | C38: =CORREL('טבלת אב'!I2:I98,'טבלת אב'!S2:S98) -> 0.29522382
B39: 'הרגשתי בטוח' מול האטה | C39: =CORREL('טבלת אב'!I2:I98,'טבלת אב'!Q2:Q98) -> -0.18583207
B41: ⑥ קבלה כללית
B42: הנאה מהחוויה (1–9) | C42: =AVERAGE('טבלת אב'!AF2:AF98) -> 7.4666667
B43: מוטיבציה להליכה ארוכה (1–9) | C43: =AVERAGE('טבלת אב'!AG2:AG98) -> 5.7333333
B44: חשו חשש כלשהו | C44: =COUNTIF('טבלת אב'!Z2:Z98,"כן") -> 30
B45: לא חשו חשש | C45: =COUNTIF('טבלת אב'!Z2:Z98,"לא") -> 46

Sheet מסקנות — אחוזים
B1: מסקנות — אחוזי האטה
B2: כל האחוזים = האטה יחסית למהירות ההליכה-לבד של כל נסיין. השניות בעמודת-צד לעיון. מדגם מלא — כל 97 הנסיינים, כולל כל הראשונים ו-139, עם ההשלמות שמולאו.
B4: ① הכלב מאט את ההליכה — והמס יורד עם ההיכרות
B5: שלב | C5: % האטה | D5: בשניות (לעיון)
B6: מפגש ראשון עם הכלב | C6: +14.3% | D6: +2.12 שנ'
B7: הליכה שנייה (אחרי היכרות) | C7: +8.2% | D7: +1.21 שנ'
B8: הרובוט מאט אנשים בכ-14% במפגש הראשון, ויורד לכ-8% כבר בהליכה השנייה. זהו הממצא המרכזי.
B10: ② התרגלות — האפקט הזמני האמיתי היחיד
B11: מדד | C11: % שיפור | D11: בשניות (לעיון)
B12: ההליכה השנייה מהירה מהראשונה | C12: 4.5% | D12: +0.90 שנ'
B13: עקבי בשני הניסויים ומובהק (p=0.0006, n=87). אנשים מסתגלים לרובוט אחרי מפגש אחד.
B15: ③ הרצועה — אפס השפעה על המהירות (בכל דרך שנבדקה)
B16: השוואה | C16: בלי רצועה | D16: עם רצועה | E16: p
B17: האטה כללית (כל B מול כל C) | C17: =AVERAGE('טבלת אב'!AO2:AO98) -> 0.11917994 | D17: =AVERAGE('טבלת אב'!AP2:AP98) -> 0.11906006 | E17: ≈
B18: מפגש ראשון | C18: +16.3% | D18: +12.2% | E18: 0.34
B19: הליכה שנייה — C→B מול B→B | C19: +6.2% (C→B) | D19: +6.6% (B→B) | E19: 0.77
B20: בלי הבדל מובהק באף השוואה: לא בהליכה עצמה, לא במפגש הראשון, ולא כהכנה להליכה הבאה. הרצועה אינה כלי מהירות. (השורה הראשונה חיה — מתעדכנת מטבלת האב.)
B22: ④ הרצועה — כן משפיעה, אבל על החוויה (סולם 1–9, לא אחוזים)
B23: מדד סובייקטיבי | C23: בלי רצועה | D23: עם רצועה
B24: תחושת ביטחון | C24: 7.01 | D24: 7.37
B25: תחושת שליטה | C25: 6.01 | D25: 6.79
B26: חשו שהכלב 'שותף' | C26: 17 נסיינים | D26: 42 נסיינים
B27: הרצועה כלי חברתי-פסיכולוגי: מעלה ביטחון, שליטה ותחושת שותפות — בלי לגעת במהירות.
B29: תמונה כוללת
B30: הכלב מאט אנשים בכ-14% בהתחלה, יורד לכ-8% אחרי היכרות (התרגלות של ~6 נקודות אחוז), ומתייצב שם. הרצועה לא משנה מהירות כלל — היא בונה אמון ותחושה. פער ה-8% הנותר הוא היעד שמודל החיזוי נועד לסגור.
B32: הערות: מדגם מלא (97 נסיינים) לאחר הוספת ההשלמות (106,123,126,136,155,168,179,181). אחוזי המפגש/הסדר מחושבים על תת-קבוצות לפי סדר ההליכות; השניות המקבילות חיות בגיליון הזמנים.

Sheet ניתוח משולב
B1: ניתוח משולב — השפעת הכלב הרובוטי על מהירות ההליכה
B2: איחוד שני הניסויים: ABC (מלא, 73 נסיינים בשלושת התנאים) + ABB (חוזר, 20 נסיינים). המדד: זמן השלמת מסלול קבוע. זמן נמוך = מהיר יותר.
B4: ① הכלב מאט את ההליכה — הממצא החזק והחוזר ביותר
B5: באיגום שני הניסויים (n=92): לבד 15.49 שנ' → מפגש ראשון עם הכלב 17.28 שנ'. 79% מהנסיינים הלכו לאט יותר עם הכלב (פער חציוני +1.50 שנ', Wilcoxon p<0.0001).
B6: האפקט חוזר בנפרד בכל ניסוי: ABC נתן +1.40 שנ' (p<1e-8), ABB נתן +2.03 שנ' (p<1e-4). עצם נוכחות הכלב — לא הרצועה — הוא שמאט.
B8: ② התרגלות אמיתית — התרומה הייחודית של ניסוי ABB
B9: בניסוי ABB כל נסיין ביצע שתי הליכות כלב זהות (בלי רצועה). זה מבודד 'התרגלות טהורה' בלי בלבול עם שינוי תנאי — מה שלא ניתן היה לבודד ב-ABC לבדו.
B10: הליכת כלב ראשונה (B1) 17.57 שנ' → הליכת כלב שנייה (B2) 16.28 שנ'. שיפור ממוצע 0.84 שנ', 68% הואצו, Wilcoxon p=0.014. אחרי מפגש אחד ההליכה השנייה מהירה יותר.
B12: ③ אבל ה'מס' של הכלב לא נעלם לגמרי
B13: גם בהליכת הכלב השנייה, אחרי ההתרגלות, הנסיינים עדיין איטיים מהליכה לבד: B2 16.28 מול A 15.29 — 79% עדיין איטיים יותר (p=0.006), פער שיורי ~1 שנ'.
B14: מסקנה: ההתרגלות מקטינה את ההאטה בערך בחצי, אך נותר מס קבוע של כשנייה על עצם ההליכה לצד הכלב.
B16: ④ הרצועה כמעט לא משנה
... B26: • ערכי p חושבו ב-Python (מבחני Wilcoxon לא-פרמטריים) בשל גודל מדגם והתפלגות — לא כנוסחת Excel. • B1/B2 בניסוי ABB מסודרים כרונולוגית (הליכת הכלב הראשונה/שנייה בזמן), ללא תלות במיקום הליכת ה-A. • נסיין 203 הוחרג כבר במקור; ערכים חסרים (תקלות/זמנים חריגים) לא נכללו בחישובים הרלוונטיים. • הזמן הוא מדד עקיף למהירות על מסלול קבוע; קבצי המהירות הגולמית של הבקר לא סופקו.

Sheet השערת הרצועה
B1: בדיקת ההשערה: האם הרצועה מגבירה הסתגלות?
B2: ההשערה שהנחתה את הצוות: הליכה עם רצועה תזרז את ההסתגלות יותר מהליכה בלי רצועה. בדיקה: מדידת השיפור מהליכת-הכלב הראשונה לשנייה (זמן ראשון פחות זמן שני; ערך חיובי = הואץ), מפוצל לפי סוג ההליכה השנייה.
B4: קבוצה | C4: N | D4: שיפור ממוצע (שנ') | E4: % שהואצו | F4: מקור
B5: הליכה שנייה = C (עם רצועה) | C5: 34 | D5: 0.71 | E5: 59% | F5: ABC
B6: הליכה שנייה = B (בלי רצועה) | C6: 27 | D6: 1.08 | E6: 81% | F6: ABC
B7: הליכה שנייה = B (בלי רצועה, אותו תנאי) | C7: 19 | D7: 0.84 | E7: 68% | F7: BB
B9: התוצאה
B10: הנתונים אינם תומכים בהשערה — ואם כבר, מצביעים לכיוון ההפוך. ההליכות שהסתיימו בלי רצועה השתפרו מעט יותר (‎+0.98 שנ' באיגום) מאלה שהסתיימו עם רצועה (‎+0.71 שנ'). ההפרש אינו מובהק (Mann-Whitney p=0.27); מבחן חד-צדדי ל'רצועה מזרזת יותר' נתן p=0.86.
B11: בדיקת הבלבול המתבקש: ההפרש ברמת הזמן בין B ל-C זעום (0.19 שנ'), כך שאינו מסביר את התוצאה.
B12: מסקנה: אין עדות שהרצועה מגבירה הסתגלות. הדבר עקבי עם הממצא שהרצועה כמעט אינה משפיעה על המהירות כלל — ההסתגלות נובעת מעצם המפגש עם הכלב, לא מהרצועה.
B14: מגבלות הבדיקה
B15: • תת-הקבוצות קטנות, וזו השוואה בין נסיינים שונים (מי שקיבל B→C אינו מי שקיבל C→B) — רעש גבוה. • זהו ניתוח quasi-experimental מבוסס-סדר, לא מבחן ישיר של השערת הרצועה. • הבדיקה הישירה תדרוש תכנון עם שתי הליכות רצועה (A,C,C) להשוואה מול BB — ניסוי המשך מוצע. • ערכי p חושבו ב-Python (Mann-Whitney).

Sheet השערת הרצועה — תחושתי
B1: בדיקת ההשערה התחושתית: האם עדיף להציג את הרצועה מוקדם?
B2: ניתוח השאלונים (לא הזמנים). ההשערה: רצועה-קודם (ואז בלי) תשפר את תחושת הביטחון יותר מבלי-קודם, או מהליכה בלי רצועה כלל. תשובה קצרה: ההשערה אינה נתמכת — אך התגלו שלושה ממצאים מעניינים יותר.
B4: ① ההשערה (תזמון הרצועה) — אינה נתמכת
B5: בדיקה | C5: תוצאה
B6: רצועה-קודם מול בלי-קודם (כל מדדי הביטחון) | C6: כל ההבדלים לא מובהקים (p>0.08)
B7: אינדקס ביטחון מורכב (ללא-רצועה) | C7: רצועה-קודם −0.11 מול בלי-קודם +0.11 · p=0.57 · Cohen d=−0.23
B8: חוצה-ניסויי: רצועה-אז-בלי מול בלי-בלי | C8: בטיחות ללא-רצועה: 7.40 מול 7.85 · p=0.49
B9: אין אפקט תזמון שניתן לזהות, והמגמה הזעירה אף הפוכה מההשערה. תזמון הרצועה אינו משנה את החוויה התחושתית — עקבי עם ממצא הזמנים, שם גם התזמון לא השפיע על ההסתגלות.
B11: ② הרצועה כן תורמת — אך כאפקט ישיר, לא תזמוני
B12: מדד (בתוך-נבדקי) | C12: ללא | D12: עם | E12: Δ · p
B13: שליטה | C13: 6.01 | D13: 6.79 | E13: +0.78 · p=0.002 ✔
B14: ביטחון | C14: 7.01 | D14: 7.37 | E14: +0.36 · p=0.076
B15: הרצועה משפרת מובהק את תחושת השליטה, ואת הביטחון במגמה — ברגע שמחזיקים בה, ללא תלות במתי הוצגה.
B17: ③ הממצא המעניין ביותר — הרצועה כ"מיישרת" (equalizer)
B18: הרצועה עוזרת הכי הרבה למי שהרגיש הכי פחות בטוח/בשליטה בלעדיה, וכמעט אינה עוזרת (ואף מפריעה מעט) למי שכבר הרגיש גבוה:
B19: רווח מהרצועה | C19: חשו נמוך (≤חציון) | D19: חשו גבוה (>חציון)
B20: רווח ביטחון | C20: +1.18 (n=40, p=0.0002) | D20: −0.56 (n=36)
B21: רווח שליטה | C21: +1.87 (n=39, p<0.0001) | D21: −0.38 (n=37)
B22: פיזור השליטה מצטמצם | C22: SD 2.40 (ללא) | D22: SD 1.81 (עם)
B23: הסתייגות סטטיסטית (חשוב מול מומחית): מתאם של "שינוי מול בסיס" מוטה שלילית מטבעו (רגרסיה-לממוצע), ולכן עוצמת האפקט כנראה מוגזמת. אך צמצום הפיזור בשליטה (2.40→1.81) והמובהקות החזקה בקבוצה הנמוכה מצביעים על אפקט-יישור אמיתי, לא ארטיפקט בלבד.
B25: ④ הרצועה אינה טובה לכולם — היא מקטבת
B26: כרבע מהנסיינים דיווחו על תחושה נמוכה יותר דווקא עם הרצועה (ביטחון: 28% ירדו, שליטה: 24% ירדו), בעוד כמחצית השתפרו (ביטחון 49%, שליטה 57%). הרצועה עוזרת לחוששים ומעט מכבידה על הבטוחים-בעצמם. (רווחי הביטחון והשליטה הולכים יחד: rho=0.69.)
B28: ⑤ רמז: הרצועה עובדת כניגוד, לא כפתיחה
B29: מי שחווה בלי-רצועה קודם ייחס לרצועה יותר שותפות: 64% מול 43% אצל רצועה-קודם (Fisher p=0.098). רמז — לא מובהק — שהרצועה בולטת יותר כתוספת שמשנה את החוויה מאשר כברירת-מחדל. אם יאושש בהמשך, זה בעצם ההפך מ"רצועה מוקדם עדיפה".
B31: תמונה כוללת: תזמון הרצועה אינו משנה את החוויה. התרומה שלה ישירה ומיידית (שליטה מובהק, ביטחון במגמה), מרוכזת במי שמרגיש פחות בשליטה — אך אינה אחידה: כרבע אף חשים פחות טוב איתה.
B33: הערות: השוואות התזמון הן בין-נסייני עם תת-קבוצות קטנות (~35 כל אחת) — רעש גבוה. ערכי p חושבו ב-Python (Wilcoxon / Mann-Whitney / Fisher / Spearman). "רווח" = דירוג עם-רצועה פחות ללא-רצועה.

Sheet ממצאים נוספים
B1: ממצאים נוספים
B2: שלושה ממצאים משלימים לניתוח המרכזי, מבוססים על אותם נתונים מאוחדים.
B4: ① הלם מפגש ראשון מול מס קבוע
B5: תכנון ABB (שתי הליכות כלב זהות) מאפשר לפצל את ההאטה לשני רכיבים:
B6: רכיב | C6: תוספת מעל לבד
B7: מפגש ראשון עם הכלב (B1−A) | C7: +1.83 שנ'
B8: מצב יציב, הליכה שנייה (B2−A) | C8: +0.99 שנ'
B9: כ-46% מ'הלם המפגש הראשון' מתאושש כבר בהליכה השנייה — אך נותר מס קבוע של כ-0.99 שנ' שאינו נעלם. ההאטה אינה רק רתיעה ראשונית; יש רכיב מתמשך.
B11: ② גודל האפקט — לא רק מובהק, אלא גדול
B12: מדד גודל אפקט (rank-biserial): 0.5 ומעלה נחשב אפקט גדול.
B13: השוואה | C13: גודל אפקט | D13: עוצמה
B14: כלב בלי רצועה מול לבד | C14: 0.58 | D14: גדול
B15: כלב עם רצועה מול לבד | C15: 0.80 | D15: גדול מאוד
B16: התרגלות (הליכה 1 מול 2) | C16: 0.37 | D16: בינוני
B17: השפעת הכלב על המהירות היא אפקט גדול — לא הבדל שולי שבמקרה יצא מובהק.
B19: ③ הכלב מגדיל את השונות בין אנשים
B20: מצב | C20: סטיית תקן (שנ')
B21: הליכה לבד | C21: 2.31
B22: הליכה עם הכלב | C22: 2.91
B23: סטיית התקן עולה בנוכחות הכלב — הרובוט אינו כופה קצב אחיד. התגובה הטרוגנית מאוד: חלק כמעט אינם מושפעים, וחלק מואטים משמעותית.
B25: הערה: ממצאים אלה חישוביים (Python) ומשלימים את הניתוח המרכזי; לא מבחני נוסחת Excel.

Sheet שאלונים — חוויה
B1: שאלונים — החוויה הסובייקטיבית
B2: דירוג עצמי בסולם 1–9 (שים לב: הסולם בפועל היה 1–9, לא 1–5 כפי שתוכנן במקור). עבור נסייני ABB מוצע ממוצע שתי הליכות ה-B.
B4: ① התחושה הסובייקטיבית משקפת בדיוק את ההאטה האובייקטיבית
B5: היגד | C5: לבד (A) | D5: כלב בלי רצועה (B) | E5: כלב עם רצועה (C)
B6: ההליכה הרגישה טבעית | C6: 8.49 | D6: 7.43 | E6: 7.34
B7: הרגשתי בטוח/ה | C7: 8.66 | D7: 7.39 | E7: 7.67
B8: שמרתי על הקצב הטבעי | C8: 8.46 | D8: 7.41 | E8: 7.40
B9: צורך לשנות קצב (גבוה=רע) | C9: 2.20 | D9: 3.53 | E9: 4.25
B10: עם הכלב, הנסיינים דירגו נמוך יותר טבעיות, ביטחון ושמירה על קצב — וגבוה יותר 'צורך לשנות קצב'. כל ההבדלים מול הליכה לבד מובהקים מאוד (Wilcoxon, p<0.001). האנשים לא רק הואטו — הם גם חשו זאת.
B12: ② הכתר: הדירוג הסובייקטיבי מנבא את הזמן האובייקטיבי (n=92)
B13: מתאם בין הדירוג בשאלון להאטה בפועל (B מדוד פחות A מדוד):
B14: דירוג סובייקטיבי | C14: מתאם עם ההאטה | D14: מובהקות
B15: 'שמרתי על הקצב' | C15: ‎−0.34 | D15: p=0.001 ✔
B16: 'הרגיש טבעי' | C16: ‎−0.26 | D16: p=0.013 ✔
B17: 'צורך לשנות קצב' | C17: ‎+0.24 | D17: p=0.024 ✔
B18: 'הרגשתי בטוח' | C18: ‎−0.16 | D18: p=0.13 (לא)
B19: מי שהרגיש ששמר על הקצב הטבעי — באמת הלך קרוב יותר למהירות ההליכה-לבד שלו. שני מקורות הנתונים (מדידה אובייקטיבית ודיווח עצמי) מאמתים זה את זה. זהו חיזוק מתודולוגי חזק לממצא ההאטה.
B21: הערה: החשש הסובייקטיבי (כן/לא) לא ניבא הבדל מובהק בזמן (מואטים +2.03 מול +1.42, p=0.38).

Sheet שאלונים — פרדוקס הרצועה
B1: שאלונים — פרדוקס הרצועה
B2: מתוך שאלון הסיכום (N≈76). הממצא המרכזי: הרצועה כמעט אינה משנה מהירות אובייקטיבית — אך משנה מהותית את החוויה.
B4: ① הרצועה משפרת תחושת ביטחון ושליטה
B5: מדד סובייקטיבי (1–9) | C5: בלי רצועה | D5: עם רצועה | E5: מובהקות
B6: רמת ביטחון אישי | C6: 7.01 | D6: 7.37 | E6: p=0.08 (מגמה, לא מובהק)
B7: מידת שליטה כללית | C7: 6.01 | D7: 6.79 | E7: p=0.002 ✔
B9: ② הרצועה הופכת את הכלב מ'מכשיר' ל'שותף'
B10: לשאלה 'באיזה מצב הרגשת שהכלב הוא שותף ופחות מכשיר טכנולוגי?':
B11: תשובה | C11: מספר נסיינים
B12: בהליכה עם רצועה | C12: 42
B13: בהליכה ללא רצועה | C13: 17
B14: לא הרגשתי הבדל | C14: 12
B15: אף פעם לא הרגשתי שותף | C15: 5
B16: פי כ-2.5 יותר נסיינים חשו שותפות עם הרצועה. זהו אפקט פסיכולוגי-חברתי חזק — ללא כל השפעה על המהירות.
B18: ③ המשמעות
B19: הרצועה אינה כלי מכני (לא מאיצה, לא מאטה) אלא כלי חברתי: היא נותנת לאדם תחושת שליטה, ביטחון וקשר. לתכנון אינטראקציית אדם-רובוט זו תובנה מרכזית — האמון נבנה מ'ידית' סמלית, לא מביצועים.
B21: רקע נוסף מהסיכום
B22: מדד כללי | C22: ערך
B23: חווית ההליכה הייתה מהנה (1–9) | C23: 7.47
B24: מוטיבציה להליכה ארוכה יותר (1–9) | C24: 5.73
B25: חשו חשש כלשהו במהלך הניסוי | C25: 30 מתוך 76 (39%)
B26: הקבלה: השערת הצוות המקורית הייתה שהרצועה מגבירה הסתגלות (מהירות). הנתונים האובייקטיביים דחו זאת (גיליון 'השערת הרצועה'). אך השאלונים מגלים שהרצועה כן חשובה — בממד הסובייקטיבי, לא במהירות.

Sheet מסקנות — קוד הרובוט
B1: מסקנות — התנהגות הרובוט בניסוי (מתוך קוד הבקר)
B2: ניתוח קוד הבקר ששלט ברובוט (Unitree Go2) בזמן הניסויים. המסקנה המרכזית: אופן פעולת הרובוט תומך בפרשנות הסיבתית של ההאטה, ומנקה את השוואת הרצועה.
B4: ① מנגנון הבקרה — רובוט מלווה שמתאים את עצמו לאדם
B5: שיטת מעקב | C5: UWB — מרחק וזווית אל האדם, בתדר 10Hz
B6: מיקום הרובוט | C6: לצד האדם (מרווח צידי יעד ≈1.17 מ׳), מעט לפנים (~0.6 מ׳)
B7: בקרת מהירות | C7: Feed-forward שמשערך את מהירות האדם ומתאים אליה (FF_GAIN=1.0)
B8: תקרת מהירות | C8: עד 2.0 מ׳/ש׳ (הוגדל מ-0.9) — הרבה מעל מהירות הליכה רגילה
B9: מי מכתיב את הקצב | C9: האדם. הרובוט מוגבל ל: מהירות האדם + 0.8 מ׳/ש׳ בלבד
B10: סוג הליכה (gait) | C10: Trot — הליכה קלאסית (SwitchGait 2)
B11: בטיחות | C11: ריחוק חירום מתחת 0.65 מ׳, התחמקות צידית, כפתור עצירה ב-UWB
B12: תיעוד גולמי | C12: קובץ CSV לכל נסיין: speed_mps + מרחק מצטבר, ב-10Hz
B14: ② המשמעות להאטה — תגובה אנושית, לא ארטיפקט של הרובוט
B15: מכיוון שהרובוט מתאים את מהירותו לאדם (feed-forward על מהירות האדם, עם תקרה של 2.0 מ׳/ש׳ — הרבה מעל קצב הליכה), הוא אינו "צוואר בקבוק" שכופה קצב איטי. האדם מוביל את הקצב והרובוט עוקב. לכן ההאטה שנמדדה (A לבד מול B/C) היא ככל הנראה תגובה התנהגותית-פסיכולוגית אמיתית של האדם להליכה לצד הרובוט — ולא תוצר-לוואי של לולאת הבקרה. זו התשובה לשאלה הראשונה שכל שופט ישאל.
B17: ③ המשמעות לרצועה — מניפולציה מכנית נקייה
B18: הבקר כולו מבוסס-UWB ואינו מכיל שום התייחסות לרצועה — הקוד זהה לחלוטין בתנאי B (בלי רצועה) ובתנאי C (עם רצועה). כלומר הרובוט התנהג מכנית בדיוק אותו דבר בשני התנאים, וההבדל היחיד היה תפיסתי-חברתי אצל האדם. זה הופך את השוואת B מול C למניפולציה נקייה של האות החברתי תוך החזקת המכניקה קבועה — חיזוק מתודולוגי ישיר לממצא "פרדוקס הרצועה".
B20: ④ ניואנס שכדאי להכיר (מגבלה הוגנת)
B21: רכיב ה-feed-forward משתמש במסנן EMA (a=0.2) על מהירות האדם — כלומר הערכת המהירות של הרובוט מפגרת מעט אחרי המציאות ברגעי האצה/האטה. פיגור זה עשוי לתרום מעט לתחושת "צורך להתאים קצב" שדיווחו הנסיינים, והוא בדיוק מה שמודל החיזוי (הגיליון הבא) נועד לתקן.
B23: ⑤ נכס שלא נוצל: קבצי מהירות גולמיים
B24: הבקר תיעד לכל נסיין קובץ CSV של מהירות ההליכה ב-10Hz (speed_mps). קיימים אם כן נתוני מהירות רציפים — עשירים בהרבה מזמן-השלמת-המסלול. מומלץ למשוך אותם לניתוח (פרופיל האצה/האטה, שונות תוך-אישית); הם גם הבסיס לאימון מודל החיזוי.
B26: תמונה כוללת: הרובוט הוא מלווה שמתאים עצמו לאדם — לא רובוט שכופה קצב. לכן ההאטה היא ממצא התנהגותי אמיתי, והרצועה נבדקה בתנאי מכני זהה לחלוטין. שני אלה מחזקים משמעותית את תוקף המסקנות מול ביקורת.
B28: הערות: הקובץ המרכזי הוא follow_controller.py; קובץ הכניסה yolo_follow.py (למרות שמו — מבוסס UWB, לא YOLO). ערכי התצורה מ-AppConfig.py.

Sheet מסקנות — מודל החיזוי
B1: מסקנות — מודל חיזוי מהירות ההליכה (XGBoost)
B2: מודל שמנבא את מהירות ההליכה של האדם ~0.36 שנ׳ קדימה (3 צעדים ב-8.3Hz), כדי שהרובוט המלווה יקדים במקום להגיב באיחור. אומן ונבדק על נתוני מהירות אמיתיים מהרובוט.
B4: ① מה המודל עושה ואיך אומן
B5: מטרה | C5: חיזוי מהירות ההליכה 3 צעדים קדימה (~0.36 שנ׳)
B6: מקור נתונים | C6: קבצי מהירות אמיתיים מהרובוט (speed_mps) — 297 קבצים
B7: שיפור מתודולוגי | C7: בעבר: HuGaDB עם מהירות מפוברקת מהאצה. כעת: מהירות נמדדת אמיתית
B8: חלוקת אימון/בדיקה | C8: לפי אדם: train/val/test נפרדים, ואימות-צולב GroupKFold (5 קפלים) — כל נסיין נבדק על מודל שלא ראה אותו
B9: מאפיינים | C9: 55: 50 לגים + ממוצעים נעים + מגמות
B10: אלגוריתם | C10: XGBoost (1000 עצים, עומק 3, lr 0.01, early stopping על val)
B12: ② ביצועים — אימות צולב (5-fold GroupKFold)
B13: מדד | C13: ערך
B14: RMSE (מודל, ממוצע CV) | C14: 0.184 ± 0.021 מ׳/ש׳
B15: MAE (מודל, ממוצע CV) | C15: 0.135 ± 0.013 מ׳/ש׳
B16: R² (ממוצע CV) | C16: 89.5% ± 1.7%
B17: שיפור מול ניחוש נאיבי (CV) | C17: 10.4% ± 1.8%
B18: שיפור מול קוד הרובוט (EMA, חלוקה בודדת) | C18: 34.6%
B19: היכן היתרון מתרכז | C19: ברגעי מעבר — האצה/האטה (שם הרובוט הנוכחי מפגר)
B21: ③ הממצא החשוב ביותר — והכי הוגן
B22: קוד הרובוט הנוכחי (מסנן EMA) דווקא גרוע יותר מניחוש נאיבי (RMSE 0.256 מול 0.191) — ההחלקה מוסיפה פיגור. לכן היתרון הגדול של המודל (34.6%, חלוקה בודדת) הוא בעיקר מול הפיגור של הרובוט, ואילו מול ניחוש נאיבי טהור השיפור צנוע יותר — ‎~10% באימות-צולב. חשוב: המספרים בטבלה עברו מ"חלוקה בודדת" (שיצאה קצת קלה: RMSE 0.168) לאימות-צולב אמין (RMSE 0.184 ± 0.021). זו האמת המדויקת — ולהציג אותה כך חזק ואמין יותר.
B24: ④ למה זה חשוב לרובוט
B25: היתרון הגדול ביותר של המודל הוא ברגעי מעבר — בדיוק כשהאדם מאיץ או מאט, שם הרובוט הנוכחי מגיב באיחור. חיזוי שמקדים ב-0.36 שנ׳ מאפשר לרובוט להתחיל לזוז בזמן במקום באיחור, ולהרגיש מסונכרן יותר עם האדם.
B27: ⑤ החיבור לניסוי — סגירת המעגל
B28: הניסוי חשף "מס האטה" שיורי של ~8% שנשאר גם אחרי התרגלות. השערת העבודה: חלק מהחיכוך נובע מכך שהרובוט מגיב באיחור לשינויי הקצב של האדם. מודל שמקדים את הקצב נועד לצמצם בדיוק את הפער הזה — כאן נסגר המעגל בין המחקר ההתנהגותי לחלק ההנדסי.
B30: תמונה כוללת: המודל מנבא מהירות הליכה ~0.36 שנ׳ קדימה. באימות-צולב (5 קפלים): RMSE 0.184 ± 0.021 ושיפור ‎~10% מול ניחוש נאיבי; מול קוד הרובוט הנוכחי — 34.6% (חלוקה בודדת), בעיקר ברגעי מעבר. הוא הצעד ההנדסי לצמצום מס-ההאטה שהניסוי חשף.
B32: הערות: שתי חולשות מתודולוגיות תוקנו — ה-early stopping רץ כעת על val (לא על הבדיקה), והתוצאה אומתה ב-GroupKFold (5 קפלים, כל אדם נבדק פעם אחת על מודל שאומן בלעדיו; טווח הקפלים RMSE 0.166–0.224). מספר ה-34.6% מול הרובוט הוא מחלוקה בודדת ולא הורץ תחת CV. מספרי המעבר/יציב מריצת-עזר קצרה, כמגמה.
